Workbook

Sheet 市民意见信息（12345）导出
A1: 2025年12月19日至2026年4月18日接诉即办市级统计表（2026年全年台账）
A2: 系统下载内容情况 | AP2: 周报分析对应内容情况 | BV2: 市中心 | CF2: 发布周报
AR3: 1 | AS3: 2 | AT3: 3 | AU3: 4 | AV3: 5 | AW3: 6 | AX3: 7 | AY3: 8 | AZ3: 9 | BA3: 10 | BB3: 11 | BC3: 12 | BD3: 13 | BE3: 14 | BF3: 15 | BG3: 16 | BH3: 17 | BI3: 18 | BJ3: 19 | BK3: 20 | BL3: 21 | BM3: 22 | BN3: 23 | BO3: 24 | BP3: 25 | BQ3: 26 | BR3: 27 | BT3: 28 | BU3: 29 | BV3: 30 | BW3: 31 | BX3: 32 | BY3: 33 | BZ3: 34 | CA3: 35 | CB3: 36 | CC3: 37 | CD3: 38 | CE3: 39 | CF3: 40 | CG3: 41
A4: 工单编号 | B4: 派单时间 | C4: 签收日期 | D4: 下达日期 | E4: 联系人 | F4: 性别 | G4: 联系电话 | H4: 来电内容 | I4: 是否需答复 | J4: 性质 | K4: 部门 | L4: 问题分类 | M4: 标题 | N4: 单位 | O4: 线路号 | P4: 清分中心修改部门 | Q4: 车队名称 | R4: 公司到期 | S4: 答复日期 | T4: 截至时间 | U4: 当前节点 | V4: 提醒次数 | W4: 核实处理 | X4: 回访情况 | Y4: 处理结果 | Z4: 纠正措施 | AA4: 跟踪检查 | AB4: 最终意见 | AC4: 满意度 | AD4: 来电主体 | AE4: 来电时间 | AF4: TSBMID | AG4: 问题分类 | AH4: 是否表扬告知单 | AI4: 集团公司指标讲评问题 | AK4: 问题分 类简述 | AL4: 问题（部室）督办 | AM4: 问题（分中心）办结 | AP4: 序号 | AQ4: 月份 | AR4: 接诉编号 | AS4: 接诉分类 | AT4: 接诉平台 | AU4: 接诉时间 | AV4: 责任部室（系统） | AW4: 所属分中心（系统） | AX4: 接诉事由 | AY4: 内容简述 | AZ4: 是否内部职工 | BA4: 是否物业 | BB4: 作风问题 | BC4: 七有五性 | BD4: 目前状态 | BE4: 办结/截止日期 | BF4: 诉求简要分析 | BG4: 责任部室 | BH4: 所属分中心 | BI4: 系统内归属单位 | BJ4: 责任划分 | BK4: 是否可回访 | BL4: 经办人员 | BM4: 是否剔除 | BN4: 是否次要责任 | BO4: 回访情况 | BP4: 派单分类 | BQ4: 多渠道投诉情况 | BR4: 重复投诉 | BS4: 诉求渠道顺序 | BT4: 拆单情况 | BU4: 岗位 | BV4: 市服务热线编号 | BW4: 集团反馈“七有五性” | BX4: 热线是否拆单 | BY4: 诉求是否主责 | BZ4: 纳入考评件 | CA4: 响应情况（联系） | CB4: 解决情况 | CC4: 满意情况 | CD4: 考核项目 | CE4: 考核月份 | CF4: 是*；否“”
A5: 网络-251219-005951-3（1个附件） | B5: 2025-12-19 09:52:13 | C5: 2025-12-19 10:22:42 | D5: 2025-12-19 10:50:52 | E5: 雷靖静 | F5: 女 | G5: 手机,15059330130; | H5: 工单来源：微信服务号，此工单内容为网民留言时填写的标题及原文。 ============================= 留言标题：公交留言原文：公交车环境不好，味道太大了，建议及时通风。以及982和365线路有时候灯突然熄灭，也不再开启。整个车内漆黑一片，体验真的不好啊…市民填写的详细地址为：区、街道：海淀区上地街道详细地址：公交车内注：因不明具体公交信息，故回拨市民注：2025年12月19日08:48分13203回拨市民，询问具体公交信息，无法接听，2025年12月19日09:20分13203回拨市民，无人接听，2025年12月19日09:50分13203回拨市民，无人接听。 | I5: 是 | J5: 诉求 | K5: 行车安全服务部 | L5: 企业政策问题 | M5: 调整服务规范 | N5: 鸿运承物业管理中心 | O5: 西苑分中心 | P5: 物管行政部 | Q5: 西苑分中心 | R5: 2025-12-26 23:59:59 | S5: 2025-12-20 | T5: 2025-12-24 08:59:59 | U5: 结束 | V5: 0 | W5: 您好，关于您反映问题的办理情况，鸿运承物业管理中心西苑分中心现对您回复如下： | X5: 我分中心已于2025年12月19日下午13点21分对您进行电话回复。办理人：于德海；部门：鸿运承物业管理中心西苑分中心；职务；物管副主任。审核人：郑楠；部门：鸿运承物业管理中心物管行政部；职务：物管员。 | Y5: 雷女士您好，982路公交车我们在西北旺场站进行车厢服务工作，365路公交车我们在永丰场站进行车厢服务工作，您所述车辆运营中公交车环境不好，味道太大了的问题，我们非常重视您的反馈，由于我们的工作没有做好，两条线路给您带来不好的乘车体验，实在是抱歉，雷女士。两条线路车辆回到我们的清洁地点后（西北旺场站、永丰场站），日常工作时段内，我们的保洁员在清理卫生的同时，已将车门、车窗全部打开，及时对车内进行了通风作业，对车内异味进行了处理，已整改完毕。 | Z5: 我们分中心及场站班组长再次与两条线路的保洁人员进行了沟通，日常工作中我们要密切关注车内空气质量，做好通风换气作业，确保给您带来一个空气清新的出行环境。 | AA5: 我们定期会召开车厢服务工作专题会议，开展专项检查，日常工作中我们加大巡检力度，强化制度建设，不断提高管理水平。 | AB5: 您好，关于您反映问题的办理情况，鸿运承物业管理中心西苑分中心现对您回复如下：雷女士您好，982路公交车我们在西北旺场站进行车厢服务工作，365路公交车我们在永丰场站进行车厢服务工作，您所述车辆运营中公交车环境不好，味道太大了的问题，我们非常重视您的反馈，由于我们的工作没有做好，两条线路给您带来不好的乘车体验，实在是抱歉，雷女士。两条线路车辆回到我们的清洁地点后（西北旺场站、永丰场站），日常工作时段内，我们的保洁员在清理卫生的同时，已将车门、车窗全部打开，及时对车内进行了通风作业，对车内异味进行了处理，已整改完毕。我们定期会召开车厢服务工作专题会议，开展专项检查，日常工作中我们加大巡检力度，强化制度建设，不断提高管理水平。我分中心已于2025年12月19日下午13点21分对您进行电话回复。我们分中心及场站班组长再次与两条线路的保洁人员进行了沟通，日常工作中我们要密切关注车内空气质量，做好通风换气作业，确保给您带来一个空气清新的出行环境。欢迎您随时对我们的工作进行监督，感谢您提出宝贵意见，给您的出行带来的不便我们和您说声抱歉，谢谢您的支持与谅解。 | AC5: 满意 | AD5: 个人 | AE5: 2025-12-18 17:36:34 | AF5: 1725545785 | AG5: 服务 | AH5: 否 | AK5: =AG5&L5&M5 -> 服务企业政策问题调整服务规范 | AP5: 1 | AQ5: 46023 | AR5: =IFERROR(LEFT(A5,FIND("（",A5)-1),A5) -> 网络-251219-005951-3 | AS5: =J5 -> 诉求 | AT5: =IF(MID(AR5,1,2)="热线",12345)+IF(MID(AR5,1,2)="网络",12345) -> 12345 | AU5: =IFERROR(LEFT(D5,FIND(" ",D5)-1),D5) -> 2025-12-19 | AV5: =P5 -> 物管行政部 | AW5: =Q5 -> 西苑分中心 | AX5: =H5 -> 工单来源：微信服务号，此工单内容为网民留言时填写的标题及原文。 ============================= 留言标题：公交留言原文：公交车环境不好，味道太大了，建议及时通风。以及982和365线路有时候灯突然熄灭，也不再开启。整个车内漆黑一片，体验真的不好啊…市民填写的详细地址为：区、街道：海淀区上地街道详细地址：公交车内注：因不明具体公交信息，故回拨市民注：2025年12月19日08:48分13203回拨市民，询问具体公交信息，无法接听，2025年12月19日09:20分13203回拨市民，无人接听，2025年12月19日09:50分13203回拨市民，无人接听。 | AY5: =AG5 -> 服务 | AZ5: 否 | BA5: 否 | BB5: 否 | BC5: 七有五性,宜居性 | BD5: =U5 -> 结束 | BE5: =IFERROR(LEFT(T5,FIND(" ",T5)-1),T5) -> 2025-12-24 | BF5: 车辆卫生问题 （车内异味） | BG5: 物管行政部 | BH5: 西苑分中心 | BL5: =IF(BG5="物管行政部","侯旭、郑楠",IF(BG5="安保部","张耕",IF(BG5="工程设备部","华菲",IF(BG5="人力资源部","成琦",IF(BG5="党委工作部","阎鑫雨",IF(BG5="餐饮服务部","赵弘晨",IF(BG5="工会","郑欣",IF(BG5="办公室","董娜",""))))))))&IF(BG5="纪检部","黄倩",IF(BG5="信息管理部","蔡浩然","")) -> 侯旭、郑楠 | BM5: 未主动剔除 | BP5: 业务类 | BV5: =MID(AR5,1,16) -> 网络-251219-005951 | BW5: 七有五性,便利性 | BX5: =IF(COUNTIF(BV:BV,BV5)=1,"否","是") -> 否 | BY5: =MID(AR5,18,1) -> 3 | BZ5: 只评价响应率 | CE5: 1月 | CG5: =VLOOKUP(AR5,[1]市民意见信息导出!$AI$2:$AK$392,3,FALSE()) -> 结束 | CH5: =VLOOKUP(BV5,[2]Sheet1!$C$2:$AC$99,2,FALSE()) -> 1月
A6: 热线-251218-074256-2（1个附件） | B6: 2025-12-18 23:00:02 | C6: 2025-12-18 23:10:41 | D6: 2025-12-19 10:20:38 | E6: 李先生 | F6: 男 | G6: 手机,15120055651; | H6: 市民反映，自己有一个东西丢在了密云区北京公交第七客运公司，上该公司门口来领东西，女工作人员的态度特别横，自己给值班人员打电话对方态度也特别横 ，12月18日10:40自己打公交公司96166后，也未处理好此问题，来电反映北京公交第七客运公司工作人员态度恶劣等问题。 | I6: 是 | J6: 诉求 | K6: 安保部（应急管理中心） | L6: 安保专业政策问题 | M6: 安保措施 | N6: 鸿运承物业管理中心 | O6: 东直门分中心 | P6: 安保部（应急管理中心） | Q6: 东直门分中心 | R6: 2025-12-25 23:59:59 | S6: 2025-12-22 | T6: 2025-12-23 08:59:59 | U6: 结束 | V6: 1 | W6: 经核实，市民反映场站职工警卫工作态度生硬不满问题，经了解乘客将物品丢失在运营车辆上，乘客打车到场站寻找，询问警卫人员，警卫人员告知需要联系车队值班人员协助寻找，其询问怎么说，警卫人员告知，跟车队人员说就可以，造成乘客误解警卫人员态度不好。造成市民不满。 | X6: 2025年12月22日11点33分，安保主任对投诉人员进行了电话回复，说明了原因。 办理人：侯映辉，东直门分中心安保主任。 | Y6: 东直门分中心安保专业针对这件事举一反三，要求各场站负责人对职工加强培训教育，并加强监督检查力度。 | Z6: 东直门分中心安保专业针对这件事举一反三，要求各场站负责人对职工加强培训教育，并加强监督检查力度。 | AA6: 东直门分中心安保专业针对此次事件进行了分析，加强对场站职工警卫培训教育，强化责任意识管理。 | AB6: 经核实，市民反映场站职工警卫工作态度生硬不满问题，经了解乘客将物品丢失在运营车辆上，乘客打车到场站寻找，询问警卫人员，警卫人员告知需要联系车队值班人员协助寻找，其询问怎么说，警卫人员告知，跟车队人员说就可以，造成乘客误解警卫人员态度不好。造成市民不满。 | AC6: 满意 | AD6: 个人 | AE6: 2025-12-18 22:44:21 | AF6: 1725545788 | AG6: 服务 | AH6: 否 | AK6: =AG6&L6&M6 -> 服务安保专业政策问题安保措施 | AP6: 2 | AQ6: 46023 | AR6: =IFERROR(LEFT(A6,FIND("（",A6)-1),A6) -> 热线-251218-074256-2 | AS6: =J6 -> 诉求 | AT6: =IF(MID(AR6,1,2)="热线",12345)+IF(MID(AR6,1,2)="网络",12345) -> 12345 | AU6: =IFERROR(LEFT(D6,FIND(" ",D6)-1),D6) -> 2025-12-19 | AV6: =P6 -> 安保部（应急管理中心） | AW6: =Q6 -> 东直门分中心 | AX6: =H6 -> 市民反映，自己有一个东西丢在了密云区北京公交第七客运公司，上该公司门口来领东西，女工作人员的态度特别横，自己给值班人员打电话对方态度也特别横 ，12月18日10:40自己打公交公司96166后，也未处理好此问题，来电反映北京公交第七客运公司工作人员态度恶劣等问题。 | AY6: =AG6 -> 服务 | AZ6: 否 | BA6: 否 | BB6: 否 | BC6: 七有五性,便利性、安全性 | BD6: =U6 -> 结束 | BE6: =IFERROR(LEFT(T6,FIND(" ",T6)-1),T6) -> 2025-12-23 | BF6: 场站安保问题 （寻找遗失物，反映工作人员态度） 同人同诉 多渠道 | BG6: 安保部 | BH6: 东直门分中心 | BL6: =IF(BG6="物管行政部","侯旭、郑楠",IF(BG6="安保部","张耕",IF(BG6="工程设备部","华菲",IF(BG6="人力资源部","成琦",IF(BG6="党委工作部","阎鑫雨",IF(BG6="餐饮服务部","赵弘晨",IF(BG6="工会","郑欣",IF(BG6="办公室","董娜",""))))))))&IF(BG6="纪检部","黄倩",IF(BG6="信息管理部","蔡浩然","")) -> 张耕 | BM6: 未主动剔除 | BP6: 业务类 | BQ6: 同人同诉该问题（先拨打96166反映，后拨打12345） 先拨打GJ-PHONE-20251218-2482-2、后拨打热线-251218-074256-2、热线-251218-074442-2 | BR6: 是 | BS6: 先96166后12345 | BV6: =MID(AR6,1,16) -> 热线-251218-074256 | BW6: 七有五性,便利性 | BX6: =IF(COUNTIF(BV:BV,BV6)=1,"否","是") -> 否 | BY6: =MID(AR6,18,1) -> 2 | CG6: =VLOOKUP(AR6,[1]市民意见信息导出!$AI$2:$AK$392,3,FALSE()) -> 结束 | CH6: =VLOOKUP(BV6,[2]Sheet1!$C$2:$AC$99,2,FALSE()) -> #N/A
A7: 热线-251219-045803（1个附件） | B7: 2025-12-19 15:20:09 | C7: 2025-12-19 15:30:24 | D7: 2025-12-19 15:48:19 | E7: 张女士 | F7: 女 | G7: 手机,15600000314; | H7: 市民反映，自己12月18日下午4点30分-5点期间在和平门公交站乘坐142路公交车，往丽泽桥方向行驶，乘车期间发现车窗上红色的小锤子以及窗框下面，很脏，落了一层灰尘，迟迟无人清理，后面也没有擦拭，都结成黑色的了，希望相关部门核实处理，来电反映希望142路及时清理车内卫生的问题。 | I7: 是 | J7: 诉求 | K7: 行车安全服务部 | L7: 企业政策问题 | M7: 调整服务规范 | N7: 鸿运承物业管理中心 | O7: 西客站分中心 | P7: 物管行政部 | Q7: 西客站分中心 | R7: 2025-12-26 23:59:59 | S7: 2025-12-20 | T7: 2025-12-24 08:59:59 | U7: 结束 | V7: 0 | W7: 您好，关于您反映问题的办理情况，鸿运承物业管理中心西客站分中心现对您回复如下： | X7: 我分中心已于2025年12月20日上午11点08分对您进行电话回复。办理人：穆鑫；部门：鸿运承物业管理中心西客站分中心；职务；物管副主任。审核人：郑楠；部门：鸿运承物业管理中心物管行政部；职务：物管员。 | Y7: 张女士您好，142路公交车我们在丽泽桥北场站进行洗车服务工作，您所述车辆运营中车内车窗上红色的小锤子以及窗框下面，很脏，落了一层灰尘，迟迟无人清理，后面也没有擦拭，都结成黑色的了的问题我们非常重视您的反馈，由于我们的工作没有做好，142路给您带来不好的乘车体验，实在是抱歉，张女士。该线路车辆回到丽泽桥北场站后，在日常工作时段内，我们的保洁员已对车内卫生进行了全面的清理，确保我们的出场车辆卫生符合企业标准。您反馈的问题我们已整改完毕，同时我们要求保洁员对142路所有运营车辆的卫生再次进行细化清理。我们对于运营车辆车内卫生的清洁工作是一直在做的，也从未停止，已经形成了长效的清洁机制，但有时候卫生清洁工作我们做的还有不尽人意之处，您多多谅解。 | Z7: 我们分中心及场站班组长再次与142路的保洁人员进行了沟通，日常工作中我们要把清洁质量做的更加细致，同时加强保洁员清洁技能的培训，熟练掌握清洁方法，确保给您带来一个干净、整洁的出行环境。 | AA7: 我们定期会召开车辆保洁专题会议，开展车辆卫生专项检查，日常工作中我们加大巡检力度，强化制度建设，不断提高管理水平。 | AB7: 您好，关于您反映问题的办理情况，鸿运承物业管理中心西客站分中心现对您回复如下：张女士您好，142路公交车我们在丽泽桥北场站进行洗车服务工作，您所述车辆运营中车内车窗上红色的小锤子以及窗框下面，很脏，落了一层灰尘，迟迟无人清理，后面也没有擦拭，都结成黑色的了的问题我们非常重视您的反馈，由于我们的工作没有做好，142路给您带来不好的乘车体验，实在是抱歉，张女士。该线路车辆回到丽泽桥北场站后，在日常工作时段内，我们的保洁员已对车内卫生进行了全面的清理，确保我们的出场车辆卫生符合企业标准。您反馈的问题我们已整改完毕，同时我们要求保洁员对142路所有运营车辆的卫生再次进行细化清理。我们对于运营车辆车内卫生的清洁工作是一直在做的，也从未停止，已经形成了长效的清洁机制，但有时候卫生清洁工作我们做的还有不尽人意之处，您多多谅解。我们定期会召开车辆保洁专题会议，开展车辆卫生专项检查，日常工作中我们加大巡检力度，强化制度建设，不断提高管理水平。我分中心已于2025年12月20日上午11点08分对您进行电话回复。我们分中心及场站班组长再次与142路的保洁人员进行了沟通，日常工作中我们要把清洁质量做的更加细致，同时加强保洁员清洁技能的培训，熟练掌握清洁方法，确保给您带来一个干净、整洁的出行环境。欢迎您随时对我们的工作进行监督，感谢您提出宝贵意见，给您的出行带来的不便我们和您说声抱歉，谢谢您的支持与谅解。 | AC7: 满意 | AD7: 个人 | AE7: 2025-12-19 15:16:36 | AF7: 1741937701 | AG7: 服务 | AH7: 否 | AK7: =AG7&L7&M7 -> 服务企业政策问题调整服务规范 | AP7: 3 | AQ7: 46023 | AR7: =IFERROR(LEFT(A7,FIND("（",A7)-1),A7) -> 热线-251219-045803 | AS7: =J7 -> 诉求 | AT7: =IF(MID(AR7,1,2)="热线",12345)+IF(MID(AR7,1,2)="网络",12345) -> 12345 | AU7: =IFERROR(LEFT(D7,FIND(" ",D7)-1),D7) -> 2025-12-19 | AV7: =P7 -> 物管行政部 | AW7: =Q7 -> 西客站分中心 | AX7: =H7 -> 市民反映，自己12月18日下午4点30分-5点期间在和平门公交站乘坐142路公交车，往丽泽桥方向行驶，乘车期间发现车窗上红色的小锤子以及窗框下面，很脏，落了一层灰尘，迟迟无人清理，后面也没有擦拭，都结成黑色的了，希望相关部门核实处理，来电反映希望142路及时清理车内卫生的问题。 | AY7: =AG7 -> 服务 | AZ7: 否 | BA7: 否 | BB7: 否 | BC7: 七有五性,宜居性 | BD7: =U7 -> 结束 | BE7: =IFERROR(LEFT(T7,FIND(" ",T7)-1),T7) -> 2025-12-24 | BF7: 车辆卫生问题 （车窗玻璃脏） | BG7: 物管行政部 | BH7: 西客站分中心 | BL7: =IF(BG7="物管行政部","侯旭、郑楠",IF(BG7="安保部","张耕",IF(BG7="工程设备部","华菲",IF(BG7="人力资源部","成琦",IF(BG7="党委工作部","阎鑫雨",IF(BG7="餐饮服务部","赵弘晨",IF(BG7="工会","郑欣",IF(BG7="办公室","董娜",""))))))))&IF(BG7="纪检部","黄倩",IF(BG7="信息管理部","蔡浩然","")) -> 侯旭、郑楠 | BM7: 未主动剔除 | BP7: 业务类 | BV7: =MID(AR7,1,16) -> 热线-251219-045803 | BW7: 七有五性,便利性 | BX7: =IF(COUNTIF(BV:BV,BV7)=1,"否","是") -> 否 | BY7: =MID(AR7,18,1) | BZ7: 只评价响应率 | CE7: 1月 | CG7: =VLOOKUP(AR7,[1]市民意见信息导出!$AI$2:$AK$392,3,FALSE()) -> 结束 | CH7: =VLOOKUP(BV7,[2]Sheet1!$C$2:$AC$99,2,FALSE()) -> 1月
A8: 热线-251218-074442-2（1个附件） | B8: 2025-12-19 17:03:20 | C8: 2025-12-19 17:10:19 | D8: 2025-12-19 18:06:50 | E8: 李先生 | F8: 男 | G8: 手机,15120055651; | H8: 市民反映，密云区北京公交第七客运公司，2025年12月18日22:15自己丢东西了来这里找东西，门口的三个女的值班人员态度非常差，自己拨打值班电话89012827态度更加恶劣，短头发值班女士态度恶劣，8907值班男士态度不好，司机态度好，但是值班人员把责任往司机身上推，希望相关部门核实处理，从自己十点十分到这儿一直现在没有任何一个工作人员跟自己处理这个事情，职能部门使用私人电话18515596640回复自己，态度差，值班人员态度差，来电反映密云区北京公交第七客运公司值班人员态度差问题。注：市民要求2025年12月19日上午十点后回复。工单流转：密云区分中心退回：经与市民核实，北京公交第七客运公司属于公交集团监管，不属于密云区域公交监管范畴，请北京市公交集团处理市民诉求。对答复不满意 | I8: 是 | J8: 其他 | K8: 安保部（应急管理中心） | L8: 安保专业其他问题 | M8: 安保专业补充内容 | N8: 鸿运承物业管理中心 | O8: 东直门分中心 | P8: 安全保卫部（应急管理中心） | Q8: 东直门分中心 | R8: 2025-12-26 23:59:59 | S8: 2025-12-22 | T8: 2025-12-24 08:59:59 | U8: 结束 | V8: 0 | W8: 经核实，市民反映场站职工警卫工作态度生硬不满问题，经了解乘客将物品丢失在运营车辆上，乘客打车到场站寻找，询问警卫人员，警卫人员告知需要联系车队值班人员协助寻找，其询问怎么说，警卫人员告知，跟车队人员说就可以，造成乘客误解警卫人员态度不好。造成市民不满。 | X8: 2025年12月22日11点33分，安保主任对投诉人员进行了电话回复，说明了原因。 办理人：侯映辉，东直门分中心安保主任。 | Y8: 东直门分中心安保专业针对这件事举一反三，要求各场站负责人对职工加强培训教育，并加强监督检查力度。 | Z8: 东直门分中心安保专业针对这件事举一反三，要求各场站负责人对职工加强培训教育，并加强监督检查力度。 | AA8: 东直门分中心安保专业针对此次事件进行了分析，加强对场站职工警卫培训教育，强化责任意识管理。 | AB8: 经核实，市民反映场站职工警卫工作态度生硬不满问题，经了解乘客将物品丢失在运营车辆上，乘客打车到场站寻找，询问警卫人员，警卫人员告知需要联系车队值班人员协助寻找，其询问怎么说，警卫人员告知，跟车队人员说就可以，造成乘客误解警卫人员态度不好。造成市民不满。 | AC8: 满意 | AD8: 个人 | AE8: 2025-12-18 22:54:16 | AF8: 1725545788 | AG8: 服务 | AH8: 否 | AK8: =AG8&L8&M8 -> 服务安保专业其他问题安保专业补充内容 | AP8: 4 | AQ8: 46023 | AR8: =IFERROR(LEFT(A8,FIND("（",A8)-1),A8) -> 热线-251218-074442-2 | AS8: =J8 -> 其他 | AT8: =IF(MID(AR8,1,2)="热线",12345)+IF(MID(AR8,1,2)="网络",12345) -> 12345 | AU8: =IFERROR(LEFT(D8,FIND(" ",D8)-1),D8) -> 2025-12-19 | AV8: =P8 -> 安全保卫部（应急管理中心） | AW8: =Q8 -> 东直门分中心 | AX8: =H8 -> 市民反映，密云区北京公交第七客运公司，2025年12月18日22:15自己丢东西了来这里找东西，门口的三个女的值班人员态度非常差，自己拨打值班电话89012827态度更加恶劣，短头发值班女士态度恶劣，8907值班男士态度不好，司机态度好，但是值班人员把责任往司机身上推，希望相关部门核实处理，从自己十点十分到这儿一直现在没有任何一个工作人员跟自己处理这个事情，职能部门使用私人电话18515596640回复自己，态度差，值班人员态度差，来电反映密云区北京公交第七客运公司值班人员态度差问题。注：市民要求2025年12月19日上午十点后回复。工单流转：密云区分中心退回：经与市民核实，北京公交第七客运公司属于公交集团监管，不属于密云区域公交监管范畴，请北京市公交集团处理市民诉求。对答复不满意 | AY8: =AG8 -> 服务 | AZ8: 否 | BA8: 否 | BB8: 否 | BC8: 七有五性,便利性、安全性 | BD8: =U8 -> 结束 | BE8: =IFERROR(LEFT(T8,FIND(" ",T8)-1),T8) -> 2025-12-24 | BF8: 场站安保问题 （寻找遗失物，反映工作人员态度） 同人同诉 多渠道 | BG8: 安保部 | BH8: 东直门分中心 | BL8: =IF(BG8="物管行政部","侯旭、郑楠",IF(BG8="安保部","张耕",IF(BG8="工程设备部","华菲",IF(BG8="人力资源部","成琦",IF(BG8="党委工作部","阎鑫雨",IF(BG8="餐饮服务部","赵弘晨",IF(BG8="工会","郑欣",IF(BG8="办公室","董娜",""))))))))&IF(BG8="纪检部","黄倩",IF(BG8="信息管理部","蔡浩然","")) -> 张耕 | BM8: 未主动剔除 | BP8: 业务类 | BQ8: 同人同诉该问题（先拨打96166反映，后拨打12345） 先拨打GJ-PHONE-20251218-2482-2、后拨打热线-251218-074256-2、热线-251218-074442-2 | BR8: 是 | BS8: 先96166后12345 | BV8: =MID(AR8,1,16) -> 热线-251218-074442 | BW8: 七有五性,便利性 | BX8: =IF(COUNTIF(BV:BV,BV8)=1,"否","是") -> 否 | BY8: =MID(AR8,18,1) -> 2 | BZ8: 只评价响应率 | CE8: 1月 | CG8: =VLOOKUP(AR8,[1]市民意见信息导出!$AI$2:$AK$392,3,FALSE()) -> 结束 | CH8: =VLOOKUP(BV8,[2]Sheet1!$C$2:$AC$99,2,FALSE()) -> 1月
A9: 网络-251220-031514 | B9: 2025-12-20 14:53:10 | C9: 2025-12-20 15:04:49 | D9: 2025-12-20 15:09:56 | E9: 保密 | F9: 女 | G9: 保密 | H9: 工单来源：微信服务号，此工单内容为网民留言时填写的标题及原文。 ============================= 留言标题：120公交车辆卫生差留言原文：今早在天坛乘坐120公交车，发现车内卫生脏，座椅有灰尘，座椅缝隙全是垃圾。希望有关部门加强管理。市民填写的详细地址为：区、街道：东城区天坛街道详细地址：天桥120公交车辆卫生差问题 | I9: 是 | J9: 诉求 | K9: 行车安全服务部 | L9: 乘车环境问题 | M9: 车辆卫生 | N9: 鸿运承物业管理中心 | O9: 动物园分中心 | P9: 物管行政部 | Q9: 动物园分中心 | R9: 2025-12-27 23:59:59 | S9: 2025-12-22 | T9: 2025-12-25 08:59:59 | U9: 结束 | V9: 0 | W9: 您好，关于您反映问题的办理情况，鸿运承物业管理中心动物园分中心现对您回复如下： | X9: 因您的联系方式保密，我们未能对您进行电话回复。办理人：杜伟；部门：鸿运承物业管理中心动物园分中心；职务；物管副主任。审核人：郑楠；部门：鸿运承物业管理中心物管行政部；职务：物管员。 | Y9: 女士您好，120路公交车我们在左家庄场站进行洗车服务工作，您所述车辆运营中车内卫生脏，座椅有灰尘，座椅缝隙全是垃圾的问题我们非常重视您的反馈，由于我们的工作没有做好，120路给您带来不好的乘车体验，实在是抱歉，女士。该线路车辆回到左家庄场站后，在日常工作时段内，我们的保洁员已对车内座椅卫生进行了全面的清理，确保我们的出场车辆卫生符合企业标准。您反馈的问题我们已整改完毕，同时我们要求保洁员对120路所有运营车辆的卫生再次进行细化清理。我们对于运营车辆车内卫生的清洁工作是一直在做的，也从未停止，已经形成了长效的清洁机制，但有时候卫生清洁工作我们做的还有不尽人意之处，您多多谅解。 | Z9: 我们分中心及场站班组长再次与120路的保洁人员进行了沟通，日常工作中我们要把清洁质量做的更加细致，同时加强保洁员清洁技能的培训，熟练掌握清洁方法，确保给您带来一个干净、整洁的出行环境。 | AA9: 我们定期会召开车辆保洁专题会议，开展车辆卫生专项检查，日常工作中我们加大巡检力度，强化制度建设，不断提高管理水平。 | AB9: 欢迎您随时对我们的工作进行监督，感谢您提出宝贵意见，给您的出行带来的不便我们和您说声抱歉，谢谢您的支持与谅解。 | AC9: 满意 | AD9: 个人 | AE9: 2025-12-20 09:53:24 | AF9: 1741937703 | AG9: 服务 | AH9: 否 | AK9: =AG9&L9&M9 -> 服务乘车环境问题车辆卫生 | AP9: 5 | AQ9: 46023 | AR9: =IFERROR(LEFT(A9,FIND("（",A9)-1),A9) -> 网络-251220-031514 | AS9: =J9 -> 诉求 | AT9: =IF(MID(AR9,1,2)="热线",12345)+IF(MID(AR9,1,2)="网络",12345) -> 12345 | AU9: =IFERROR(LEFT(D9,FIND(" ",D9)-1),D9) -> 2025-12-20 | AV9: =P9 -> 物管行政部 | AW9: =Q9 -> 动物园分中心 | AX9: =H9 -> 工单来源：微信服务号，此工单内容为网民留言时填写的标题及原文。 ============================= 留言标题：120公交车辆卫生差留言原文：今早在天坛乘坐120公交车，发现车内卫生脏，座椅有灰尘，座椅缝隙全是垃圾。希望有关部门加强管理。市民填写的详细地址为：区、街道：东城区天坛街道详细地址：天桥120公交车辆卫生差问题 | AY9: =AG9 -> 服务 | AZ9: 否 | BA9: 否 | BB9: 否 | BC9: 七有五性,宜居性 | BD9: =U9 -> 结束 | BE9: =IFERROR(LEFT(T9,FIND(" ",T9)-1),T9) -> 2025-12-25 | BF9: 车辆卫生问题 （车内卫生脏、座椅脏） | BG9: 物管行政部 | BH9: 动物园分中心 | BL9: =IF(BG9="物管行政部","侯旭、郑楠",IF(BG9="安保部","张耕",IF(BG9="工程设备部","华菲",IF(BG9="人力资源部","成琦",IF(BG9="党委工作部","阎鑫雨",IF(BG9="餐饮服务部","赵弘晨",IF(BG9="工会","郑欣",IF(BG9="办公室","董娜",""))))))))&IF(BG9="纪检部","黄倩",IF(BG9="信息管理部","蔡浩然","")) -> 侯旭、郑楠 | BM9: 未主动剔除 | BP9: 业务类 | BV9: =MID(AR9,1,16) -> 网络-251220-031514 | BW9: 七有五性,便利性 | BX9: =IF(COUNTIF(BV:BV,BV9)=1,"否","是") -> 否 | BY9: =MID(AR9,18,1) | CG9: =VLOOKUP(AR9,[1]市民意见信息导出!$AI$2:$AK$392,3,FALSE()) -> 结束 | CH9: =VLOOKUP(BV9,[2]Sheet1!$C$2:$AC$99,2,FALSE()) -> #N/A
A10: 网络-251221-010505 | B10: 2025-12-21 10:30:51 | C10: 2025-12-21 10:45:49 | D10: 2025-12-21 11:07:04 | E10: 保密 | F10: 女 | G10: 保密 | H10: 工单来源：微信服务号，此工单内容为网民留言时填写的标题及原文。============================= 留言标题：362车卫生问题留言原文：今天下午从人民医院看完病在西直门南座362公交车,上车发现扶手又黑又脏,现在冬季传染病多车内卫生差.容易交叉感染。希望改正加强管理。市民填写的详细地址为：区、街道：海淀区花园路街道详细地址：西直门 | I10: 是 | J10: 诉求 | K10: 行车安全服务部 | L10: 乘车环境问题 | M10: 车辆卫生 | N10: 鸿运承物业管理中心 | O10: 动物园分中心 | P10: 物管行政部 | Q10: 动物园分中心 | R10: 2025-12-28 23:59:59 | S10: 2025-12-22 | T10: 2025-12-26 08:59:59 | U10: 结束 | V10: 0 | W10: 您好，关于您反映问题的办理情况，鸿运承物业管理中心动物园分中心现对您回复如下： | X10: 因您的联系方式保密，我们未能对您进行电话回复。办理人：杜伟；部门：鸿运承物业管理中心动物园分中心；职务；物管副主任。审核人：郑楠；部门：鸿运承物业管理中心物管行政部；职务：物管员。 | Y10: 女士您好，362路公交车我们在西直门南场站进行洗车服务工作，您所述车辆运营中扶手又黑又脏的问题我们非常重视您的反馈，由于我们的工作没有做好，362路给您带来不好的乘车体验，实在是抱歉，女士。该线路车辆回到西直门南场站后，在日常工作时段内，我们的保洁员已对车内扶手卫生进行了全面的清理，确保我们的出场车辆卫生符合企业标准。您反馈的问题我们已整改完毕，同时我们要求保洁员对362路所有运营车辆的卫生再次进行细化清理。我们对于运营车辆车内卫生的清洁工作是一直在做的，也从未停止，已经形成了长效的清洁机制，但有时候卫生清洁工作我们做的还有不尽人意之处，您多多谅解。 | Z10: 我们分中心及场站班组长再次与362路的保洁人员进行了沟通，日常工作中我们要把清洁质量做的更加细致，同时加强保洁员清洁技能的培训，熟练掌握清洁方法，确保给您带来一个干净、整洁的出行环境。 | AA10: 我们定期会召开车辆保洁专题会议，开展车辆卫生专项检查，日常工作中我们加大巡检力度，强化制度建设，不断提高管理水平。 | AB10: 欢迎您随时对我们的工作进行监督，感谢您提出宝贵意见，给您的出行带来的不便我们和您说声抱歉，谢谢您的支持与谅解。 | AC10: 满意 | AD10: 个人 | AE10: 2025-12-20 18:13:34 | AF10: 1741937703 | AG10: 服务 | AH10: 否 | AK10: =AG10&L10&M10 -> 服务乘车环境问题车辆卫生 | AP10: 6 | AQ10: 46023 | AR10: =IFERROR(LEFT(A10,FIND("（",A10)-1),A10) -> 网络-251221-010505 | AS10: =J10 -> 诉求 | AT10: =IF(MID(AR10,1,2)="热线",12345)+IF(MID(AR10,1,2)="网络",12345) -> 12345 | AU10: =IFERROR(LEFT(D10,FIND(" ",D10)-1),D10) -> 2025-12-21 | AV10: =P10 -> 物管行政部 | AW10: =Q10 -> 动物园分中心 | AX10: =H10 -> 工单来源：微信服务号，此工单内容为网民留言时填写的标题及原文。============================= 留言标题：362车卫生问题留言原文：今天下午从人民医院看完病在西直门南座362公交车,上车发现扶手又黑又脏,现在冬季传染病多车内卫生差.容易交叉感染。希望改正加强管理。市民填写的详细地址为：区、街道：海淀区花园路街道详细地址：西直门 | AY10: =AG10 -> 服务 | AZ10: 否 | BA10: 否 | BB10: 否 | BC10: 七有五性,宜居性 | BD10: =U10 -> 结束 | BE10: =IFERROR(LEFT(T10,FIND(" ",T10)-1),T10) -> 2025-12-26 | BF10: 车辆卫生问题 （车内扶手脏） | BG10: 物管行政部 | BH10: 动物园分中心 | BL10: =IF(BG10="物管行政部","侯旭、郑楠",IF(BG10="安保部","张耕",IF(BG10="工程设备部","华菲",IF(BG10="人力资源部","成琦",IF(BG10="党委工作部","阎鑫雨",IF(BG10="餐饮服务部","赵弘晨",IF(BG10="工会","郑欣",IF(BG10="办公室","董娜",""))))))))&IF(BG10="纪检部","黄倩",IF(BG10="信息管理部","蔡浩然","")) -> 侯旭、郑楠 | BM10: 未主动剔除 | BP10: 业务类 | BV10: =MID(AR10,1,16) -> 网络-251221-010505 | BW10: 七有五性,便利性 | BX10: =IF(COUNTIF(BV:BV,BV10)=1,"否","是") -> 否 | BY10: =MID(AR10,18,1) | CG10: =VLOOKUP(AR10,[1]市民意见信息导出!$AI$2:$AK$392,3,FALSE()) -> 结束 | CH10: =VLOOKUP(BV10,[2]Sheet1!$C$2:$AC$99,2,FALSE()) -> #N/A
A11: 热线-251221-020766-1（1个附件） | B11: 2025-12-21 15:27:36 | C11: 2025-12-21 15:30:26 | D11: 2025-12-21 15:47:06 | E11: 张女士 | F11: 女 | G11: 手机,15600091981; | H11: 市民反映，自己是北京公交集团鸿运承物业管理中心方庄分中心的职工，领导给自己发了一条通知要求12月上网课（匠心筑梦技能领航主题线上活动），没有说是自主学还是必须学，市民问领导该网课是否是必须上的，领导不予正面回复，问工会和党委书记不仅不答复市民还对市民大呼小叫，如果必须上的企业该给自己承担和网费，休息时间学要付加班费，注册地址：北京市西城区南礼士路44号，来电反映企业领导的指示不明确及工会和党委书记态度不好不作为问题。企业领导的指示不明确及工会和党委书记态度不好不作为问题企业领导的指示不明确及工会和党委书记态度不好不作为问题组织人力 | I11: 是 | J11: 诉求 | K11: 党委组织部（统战部） | L11: 领导干部问题 | M11: 领导行为不当 | N11: 鸿运承物业管理中心 | O11: 党委工作部 | P11: 党委工作部 | Q11: 机关 | R11: 2025-12-28 23:59:59 | S11: 2025-12-22 | T11: 2025-12-26 08:59:59 | U11: 结束 | V11: 0 | W11: 接到市民反映的问题后，我们立即进行了核实，经核实，与实际情况不符。 | X11: 接到市民反映的问题后，党委工作部立即进行核实，经核实，投诉内容与事实不符，不存在投诉人反映的情况，方庄分中心不存在管理人员大喊大叫的行为，感谢职工对我们工作中的不足提出宝贵意见，党委工作部会继续做好干部监督管理。办理人：高伟；部门：鸿运承物业管理中心党委工作部；职务：党委工作部副部长。审核人：吕东霞；职务：党委工作部部长。 | Y11: 无。 | Z11: 无。 | AA11: 无。 | AB11: 接到市民反映的问题后，党委工作部立即进行核实，经核实，投诉内容与事实不符，不存在投诉人反映的情况，方庄分中心不存在管理人员大喊大叫的行为，感谢职工对我们工作中的不足提出宝贵意见，党委工作部会继续做好干部监督管理。 | AC11: 满意 | AD11: 个人 | AE11: 2025-12-21 13:15:02 | AF11: 1047563 | AG11: 劳动合同及用工管理 | AH11: 否 | AK11: =AG11&L11&M11 -> 劳动合同及用工管理领导干部问题领导行为不当 | AP11: 7 | AQ11: 46023 | AR11: =IFERROR(LEFT(A11,FIND("（",A11)-1),A11) -> 热线-251221-020766-1 | AS11: =J11 -> 诉求 | AT11: =IF(MID(AR11,1,2)="热线",12345)+IF(MID(AR11,1,2)="网络",12345) -> 12345 | AU11: =IFERROR(LEFT(D11,FIND(" ",D11)-1),D11) -> 2025-12-21 | AV11: =P11 -> 党委工作部 | AW11: =Q11 -> 机关 | AX11: =H11 -> 市民反映，自己是北京公交集团鸿运承物业管理中心方庄分中心的职工，领导给自己发了一条通知要求12月上网课（匠心筑梦技能领航主题线上活动），没有说是自主学还是必须学，市民问领导该网课是否是必须上的，领导不予正面回复，问工会和党委书记不仅不答复市民还对市民大呼小叫，如果必须上的企业该给自己承担和网费，休息时间学要付加班费，注册地址：北京市西城区南礼士路44号，来电反映企业领导的指示不明确及工会和党委书记态度不好不作为问题。企业领导的指示不明确及工会和党委书记态度不好不作为问题企业领导的指示不明确及工会和党委书记态度不好不作为问题组织人力 | AY11: =AG11 -> 劳动合同及用工管理 | AZ11: 是 | BA11: 是 | BB11: 否 | BC11: 七有五性,公正性 | BD11: =U11 -> 结束 | BE11: =IFERROR(LEFT(T11,FIND(" ",T11)-1),T11) -> 2025-12-26 | BF11: 管理人员工作态度 （网上培训学习）拆单 | BG11: 党委工作部 | BH11: 机关 | BL11: =IF(BG11="物管行政部","侯旭、郑楠",IF(BG11="安保部","张耕",IF(BG11="工程设备部","华菲",IF(BG11="人力资源部","成琦",IF(BG11="党委工作部","阎鑫雨",IF(BG11="餐饮服务部","赵弘晨",IF(BG11="工会","郑欣",IF(BG11="办公室","董娜",""))))))))&IF(BG11="纪检部","黄倩",IF(BG11="信息管理部","蔡浩然","")) -> 阎鑫雨 | BM11: 未主动剔除 | BP11: 政策类 | BQ11: 拆单问题（内部职工拨打） | BT11: 由党工部、人力资源办理 | BV11: =MID(AR11,1,16) -> 热线-251221-020766 | BW11: 七有五性,劳有所得 | BX11: =IF(COUNTIF(BV:BV,BV11)=1,"否","是") -> 是 | BY11: =MID(AR11,18,1) -> 1 | BZ11: 只评价响应率 | CE11: 1月 | CG11: =VLOOKUP(AR11,[1]市民意见信息导出!$AI$2:$AK$392,3,FALSE()) -> 结束 | CH11: =VLOOKUP(BV11,[2]Sheet1!$C$2:$AC$99,2,FALSE()) -> 1月
A12: 热线-251221-020766-2（1个附件） | B12: 2025-12-21 15:27:36 | C12: 2025-12-21 15:30:26 | D12: 2025-12-21 15:47:05 | E12: 张女士 | F12: 女 | G12: 手机,15600091981; | H12: 市民反映，自己是北京公交集团鸿运承物业管理中心方庄分中心的职工，领导给自己发了一条通知要求12月上网课（匠心筑梦技能领航主题线上活动），没有说是自主学还是必须学，市民问领导该网课是否是必须上的，领导不予正面回复，问工会和党委书记不仅不答复市民还对市民大呼小叫，如果必须上的企业该给自己承担和网费，休息时间学要付加班费，注册地址：北京市西城区南礼士路44号，来电反映企业领导的指示不明确及工会和党委书记态度不好不作为问题。企业领导的指示不明确及工会和党委书记态度不好不作为问题企业领导的指示不明确及工会和党委书记态度不好不作为问题组织人力 | I12: 是 | J12: 诉求 | K12: 人力资源部（人力资源发展中心） | L12: 培训及福利 | M12: 职工培训 | N12: 鸿运承物业管理中心 | O12: 方庄分中心 | P12: 人力资源部 | Q12: 方庄分中心 | R12: 2025-12-28 23:59:59 | S12: 2025-12-22 | T12: 2025-12-26 08:59:59 | U12: 结束 | V12: 0 | W12: 经核实，来电人反映情况与实际不符，接到诉求后第一时间给职工讲解“匠心筑梦 技能领航”主题线上活动通知内容。 | X12: 2025年12月22日 上午11点02分电话回复来电人，我分中心劳动专业接到诉求后，第一时间给职工讲解“匠心筑梦 技能领航”主题线上活动通知内容，并进一步给职工解释本次活动以专栏学习、知识竞赛形式开展，职工可自愿参加。经过与来电人沟通，来电人表示知晓。办理人：吕琦，鸿运承物业管理中心方庄分中心，职务一般管理；审核人：高强；部门：鸿运承物业管理中心人力资源部；职务：中级管理。 | Y12: 2025年12月22日 上午11点02分电话回复来电人，我分中心劳动专业接到诉求后，第一时间给职工讲解“匠心筑梦 技能领航”主题线上活动通知内容，并进一步给职工解释本次活动以专栏学习、知识竞赛形式开展，职工可自愿参加。经过与来电人沟通，来电人表示知晓。 | Z12: 无 | AA12: 无 | AB12: 2025年12月22日 上午11点02分电话回复来电人，我分中心劳动专业接到诉求后，第一时间给职工讲解“匠心筑梦 技能领航”主题线上活动通知内容，并进一步给职工解释本次活动以专栏学习、知识竞赛形式开展，职工可自愿参加。经过与来电人沟通，来电人表示知晓。 | AC12: 满意 | AD12: 个人 | AE12: 2025-12-21 13:15:02 | AF12: 1741937709 | AG12: 劳动合同及用工管理 | AH12: 否 | AK12: =AG12&L12&M12 -> 劳动合同及用工管理培训及福利职工培训 | AP12: 8 | AQ12: 46023 | AR12: =IFERROR(LEFT(A12,FIND("（",A12)-1),A12) -> 热线-251221-020766-2 | AS12: =J12 -> 诉求 | AT12: =IF(MID(AR12,1,2)="热线",12345)+IF(MID(AR12,1,2)="网络",12345) -> 12345 | AU12: =IFERROR(LEFT(D12,FIND(" ",D12)-1),D12) -> 2025-12-21 | AV12: =P12 -> 人力资源部 | AW12: =Q12 -> 方庄分中心 | AX12: =H12 -> 市民反映，自己是北京公交集团鸿运承物业管理中心方庄分中心的职工，领导给自己发了一条通知要求12月上网课（匠心筑梦技能领航主题线上活动），没有说是自主学还是必须学，市民问领导该网课是否是必须上的，领导不予正面回复，问工会和党委书记不仅不答复市民还对市民大呼小叫，如果必须上的企业该给自己承担和网费，休息时间学要付加班费，注册地址：北京市西城区南礼士路44号，来电反映企业领导的指示不明确及工会和党委书记态度不好不作为问题。企业领导的指示不明确及工会和党委书记态度不好不作为问题企业领导的指示不明确及工会和党委书记态度不好不作为问题组织人力 | AY12: =AG12 -> 劳动合同及用工管理 | AZ12: 是 | BA12: 是 | BB12: 否 | BC12: 七有五性,公正性 | BD12: =U12 -> 结束 | BE12: =IFERROR(LEFT(T12,FIND(" ",T12)-1),T12) -> 2025-12-26 | BF12: 劳动人员管理及劳动纪律 （网上培训学习）拆单 | BG12: 人力资源部 | BH12: 方庄分中心 | BL12: =IF(BG12="物管行政部","侯旭、郑楠",IF(BG12="安保部","张耕",IF(BG12="工程设备部","华菲",IF(BG12="人力资源部","成琦",IF(BG12="党委工作部","阎鑫雨",IF(BG12="餐饮服务部","赵弘晨",IF(BG12="工会","郑欣",IF(BG12="办公室","董娜",""))))))))&IF(BG12="纪检部","黄倩",IF(BG12="信息管理部","蔡浩然","")) -> 成琦 | BM12: 未主动剔除 | BP12: 政策类 | BQ12: 拆单问题（内部职工拨打） | BT12: 由党工部、人力资源办理 | BV12: =MID(AR12,1,16) -> 热线-251221-020766 | BW12: 七有五性,劳有所得 | BX12: =IF(COUNTIF(BV:BV,BV12)=1,"否","是") -> 是 | BY12: =MID(AR12,18,1) -> 2 | BZ12: 只评价响应率 | CE12: 1月 | CG12: =VLOOKUP(AR12,[1]市民意见信息导出!$AI$2:$AK$392,3,FALSE()) -> 结束 | CH12: =VLOOKUP(BV12,[2]Sheet1!$C$2:$AC$99,2,FALSE()) -> 1月
A13: 热线-251222-018664（3个附件） | B13: 2025-12-22 10:56:00 | C13: 2025-12-22 11:28:39 | D13: 2025-12-22 11:29:48 | E13: 胡亚静女士 | F13: 女 | G13: 手机,13716588237; | H13: 市民反映，市民是公交集团鸿运承物业管理中心的职工，鸿运承物业管理中心作为公交集团的下属二级单位，从2022年7月1日至2023年8月，鸿运承物业管理中心违背北京公交集团下发的红头文件内容，违法给部分综合站务员B岗C岗职工转为综合站务员A岗，这些转岗人员并没有履行集团公司下发红头文件的综合站务员A岗岗位职责等内容，直接目的是为了追求A岗工资，这番操作直接浪费了公交集团大量资金，从而使综合站务员A岗人员杂乱不堪，以至于综合站务员A岗人员称呼多样，如老综A，旧综A，原综A，后转综A，现在又弄出新综A，从今年3月份开始，鸿运承在没有任何集团下发文件的前提下，把违规转岗的A岗职工保护起来，反而针对性给受红头文件保护的职工恶意调岗，共进行三次恶意调岗，性质特别恶劣，致使被针对职工，身心收到严重创伤，11月27日鸿运承人力资源部经理和工会主席，都承认此次改革是在没有集团公司相关书面文件前提下进行的，在我们坚持一切以劳动法为根基的基础上，他们承诺去和集团领导协商获取有效文件，并且还承诺一定会给职工明确答复，有录音为证，但现在在没有任何答复的前提下，12月26日已经停止排班，已下发排班表，我们职工真心不明白，身为下属二级单位领导，身为共产党干部，怎么会做出霸权主义的事情，敬请北京公交集团相关领导给予职工明确回复，职工姓名：胡亚静，来电反映敬请北京公交集团相关领导给予职工明确回复的问题。 | I13: 是 | J13: 诉求 | K13: 人力资源部（人力资源发展中心） | L13: 工资及五险二金 | M13: 工资方面 | N13: 鸿运承物业管理中心 | O13: 凌家庙分中心 | P13: 人力资源部 | Q13: 凌家庙分中心 | R13: 2025-12-29 23:59:59 | S13: 2025-12-25 | T13: 2025-12-27 08:59:59 | U13: 结束 | V13: 1 | W13: 经核实，与来电人所述情况存在出入。来电人胡亚静为我单位凌家庙分中心职工，此前我单位并未对来电人进行转岗，不涉及来电人所述的恶意调岗问题。本次企业改革是根据《鸿运承物业管理中心综合站务员优化配置改革工作实施方案》、《鸿运承物业管理中心综合站务员A岗管理规定（试行）》等制度文件开展，我单位为落选的原综A人员提供4类转岗安置方案。此前我单位凌家庙分中心于2025年11月27日、12月11日以及22日多次与来电人进行面对面的沟通，来电人均表示坚决拒绝调整A岗安置工作。 | X13: 经核实，与来电人所述情况存在出入。来电人胡亚静为我单位凌家庙分中心职工，此前我单位并未对来电人进行转岗，不涉及来电人所述的恶意调岗问题。本次企业改革是根据《鸿运承物业管理中心综合站务员优化配置改革工作实施方案》、《鸿运承物业管理中心综合站务员A岗管理规定（试行）》等制度文件开展，我单位为落选的原综A人员提供4类转岗安置方案。此前我单位凌家庙分中心于2025年11月27日、12月11日以及22日多次与来电人进行面对面的沟通，来电人均表示坚决拒绝调整A岗安置工作。 接到诉求后，我单位凌家庙分中心于2025年12月25日9点53分电话回复来电人，来电人将电话挂断，故我单位再次通过短信形式告知来电人办理结果。 办理人：王跃，鸿运承物业管理中心凌家庙分中心，职务：一般管理； 审核人：高强；部门：鸿运承物业管理中心人力资源部；职务：中级管理。 | Y13: 接到诉求后，我单位凌家庙分中心于2025年12月25日9点53分电话回复来电人，来电人将电话挂断，故我单位再次通过短信形式告知来电人办理结果。 | Z13: 无 | AA13: 无 | AB13: 经核实，与来电人所述情况存在出入。来电人胡亚静为我单位凌家庙分中心职工，此前我单位并未对来电人进行转岗，不涉及来电人所述的恶意调岗问题。本次企业改革是根据《鸿运承物业管理中心综合站务员优化配置改革工作实施方案》、《鸿运承物业管理中心综合站务员A岗管理规定（试行）》等制度文件开展，我单位为落选的原综A人员提供4类转岗安置方案。此前我单位凌家庙分中心于2025年11月27日、12月11日以及22日多次与来电人进行面对面的沟通，来电人均表示坚决拒绝调整A岗安置工作。 接到诉求后，我单位凌家庙分中心于2025年12月25日9点53分电话回复来电人，来电人将电话挂断，故我单位再次通过短信形式告知来电人办理结果。 | AC13: 满意 | AD13: 个人 | AE13: 2025-12-22 10:37:01 | AF13: 1862108387 | AG13: 运营调度 | AH13: 否 | AK13: =AG13&L13&M13 -> 运营调度工资及五险二金工资方面 | AP13: 9 | AQ13: 46023 | AR13: =IFERROR(LEFT(A13,FIND("（",A13)-1),A13) -> 热线-251222-018664 | AS13: =J13 -> 诉求 | AT13: =IF(MID(AR13,1,2)="热线",12345)+IF(MID(AR13,1,2)="网络",12345) -> 12345 | AU13: =IFERROR(LEFT(D13,FIND(" ",D13)-1),D13) -> 2025-12-22 | AV13: =P13 -> 人力资源部 | AW13: =Q13 -> 凌家庙分中心 | AX13: =H13 -> 市民反映，市民是公交集团鸿运承物业管理中心的职工，鸿运承物业管理中心作为公交集团的下属二级单位，从2022年7月1日至2023年8月，鸿运承物业管理中心违背北京公交集团下发的红头文件内容，违法给部分综合站务员B岗C岗职工转为综合站务员A岗，这些转岗人员并没有履行集团公司下发红头文件的综合站务员A岗岗位职责等内容，直接目的是为了追求A岗工资，这番操作直接浪费了公交集团大量资金，从而使综合站务员A岗人员杂乱不堪，以至于综合站务员A岗人员称呼多样，如老综A，旧综A，原综A，后转综A，现在又弄出新综A，从今年3月份开始，鸿运承在没有任何集团下发文件的前提下，把违规转岗的A岗职工保护起来，反而针对性给受红头文件保护的职工恶意调岗，共进行三次恶意调岗，性质特别恶劣，致使被针对职工，身心收到严重创伤，11月27日鸿运承人力资源部经理和工会主席，都承认此次改革是在没有集团公司相关书面文件前提下进行的，在我们坚持一切以劳动法为根基的基础上，他们承诺去和集团领导协商获取有效文件，并且还承诺一定会给职工明确答复，有录音为证，但现在在没有任何答复的前提下，12月26日已经停止排班，已下发排班表，我们职工真心不明白，身为下属二级单位领导，身为共产党干部，怎么会做出霸权主义的事情，敬请北京公交集团相关领导给予职工明确回复，职工姓名：胡亚静，来电反映敬请北京公交集团相关领导给予职工明确回复的问题。 | AY13: =AG13 -> 运营调度 | AZ13: 是 | BA13: 是 | BB13: 否 | BC13: 七有五性,公正性 | BD13: =U13 -> 结束 | BE13: =IFERROR(LEFT(T13,FIND(" ",T13)-1),T13) -> 2025-12-27 | BF13: 劳动人员调配及薪酬 （公开选聘综A岗-学历问题） 多渠道同人同诉 | BG13: 人力资源部 | BH13: 凌家庙分中心 | BL13: =IF(BG13="物管行政部","侯旭、郑楠",IF(BG13="安保部","张耕",IF(BG13="工程设备部","华菲",IF(BG13="人力资源部","成琦",IF(BG13="党委工作部","阎鑫雨",IF(BG13="餐饮服务部","赵弘晨",IF(BG13="工会","郑欣",IF(BG13="办公室","董娜",""))))))))&IF(BG13="纪检部","黄倩",IF(BG13="信息管理部","蔡浩然","")) -> 成琦 | BM13: 未主动剔除 | BP13: 政策类 | BQ13: 综A公开招聘，针对政策条件不认可。（同人同诉）：热线-250611-039775、热线-250611-059472-1、热线-250618-048072-1、热线-250708-035022、热线-251222-018664 | BR13: 是 | BS13: 先96166后12345 | BV13: =MID(AR13,1,16) -> 热线-251222-018664 | BW13: 七有五性,便利性 | BX13: =IF(COUNTIF(BV:BV,BV13)=1,"否","是") -> 否 | BY13: =MID(AR13,18,1) | CG13: =VLOOKUP(AR13,[1]市民意见信息导出!$AI$2:$AK$392,3,FALSE()) -> 结束 | CH13: =VLOOKUP(BV13,[2]Sheet1!$C$2:$AC$99,2,FALSE()) -> #N/A
A14: 网络-251222-008037（1个附件） | B14: 2025-12-22 09:15:32 | C14: 2025-12-22 09:41:01 | D14: 2025-12-22 11:29:48 | E14: 倪大伟 | F14: 男 | G14: 手机,13681321121; | H14: 工单来源：微信服务号，此工单内容为网民留言时填写的标题及原文。 ============================= 留言标题：投诉公交集团压榨员工留言原文：尊敬的北京公交鸿运承物业管理有限公司领导 / 上级主管部门： 您好！ 我是贵公司的一名老员工的家属。我怀着非常沉重和无奈的心情，向您反映公司近期对我爱人进行的不合理调岗降薪问题。 一、 本人基本情况与工作履历我爱你自进入公交系统工作，至今已有31年工龄。其中，她在运营一线担任调度员长达20多年，积累了丰富的管理经验和业务能力。2022年，转岗至北京公交鸿运承物业管理有限公司，担任综合站务员A岗，至今已在该岗位稳定工作3年。 二、 投诉事由：不合理的“岗变薪变”与学历歧视近期，公司以持有“红头文件”为由，突然要求综合站务员A岗必须具备大专学历，并以此为由要求我爱人转岗降薪。我认为这一决定极不合理，理由如下： 1. 岗位实质未变，能力完全胜任：目前的综合站务员A岗，其岗位职责与我爱人过去三年所从事的工作基本一致。我爱人在公交系统工作31年，拥有20多年调度经验和3年A岗实操经验，我爱人的业务能力和工作表现完全能够胜任当前岗位。公司在我爱人已熟练掌握岗位技能的情况下，突然以“学历”卡人，属于典型的形式主义，忽视了员工的实际工作能力。​2. 临近退休，此举缺乏人文关怀：我爱人距离法定退休年龄仅剩两年多。在企业工作了大半辈子，临近退休却面临如此大幅度的降薪，这对我爱人的生活和精神造成了巨大打击。公司的这种做法，严重违背了《劳动合同法》中关于“在本单位连续工作满十五年且距法定退休年龄不足五年的，用人单位不得依照本法第四十条、第四十一条的规定解除劳动合同”的精神，虽然公司未直接解除合同，但通过降薪逼迫员工离职，性质同样恶劣。 三、 协商过程中的不公待遇在与公司协商过程中，公司给出了四项安置方案，实则是“霸王条款”： 1. 转岗至综合站务员C岗： 工资从原A岗的（岗资3700+绩效4720）降至（岗资3100+绩效2720），降幅超过30%，这是我无法接受的。​2. 转岗至巡检员： 同样面临降薪。​3. 买断工龄。​4. 如不选择以上方案，则视为“下岗代工”。 由于我爱人拒绝签字同意这种不合理的降薪，公司相关人员频繁找我爱人“约谈”。这种高频次的约谈已经严重干扰了我爱人的正常工作和生活，导致我爱人精神压力巨大，身心状态极差。 四、 诉求综上所述，我恳请公司： 1. 立即停止这种针对老员工的不合理调岗降薪行为，尊重我31年的工作贡献和实际业务能力。​2. 维持我爱人目前的综合站务员A岗待遇，直至退休。​3. 停止高频次的施压约谈，给老员工一个安稳的工作环境。 我希望公司能从实际出发，妥善解决我爱人的问题，不要让一名即将退休的老员工寒心。 此致敬礼 市民填写的详细地址为：区：朝阳区街道：不详详细地址：北京市公共交通有限公司鸿运城物业中心 | I14: 是 | J14: 诉求 | K14: 人力资源部（人力资源发展中心） | L14: 工资及五险二金 | M14: 工资方面 | N14: 鸿运承物业管理中心 | O14: 人力资源部 | P14: 人力资源部 | Q14: 机关 | R14: 2025-12-29 23:59:59 | S14: 2025-12-23 | T14: 2025-12-27 08:59:59 | U14: 结束 | V14: 0 | W14: 经核实，与来电人所述情况存在出入：1.本次企业改革是根据《鸿运承物业管理中心综合站务员优化配置改革工作实施方案》、《鸿运承物业管理中心综合站务员A岗管理规定（试行）》等制度文件开展，综合站务员A岗岗位职责，管理方式均发生改变，现综合站务员A岗负责物业场站和人员的现场管理，以及辅助客运单位开展驾驶员安全叮嘱工作，与诉求中“岗位实质未变”存在出入。 2.企业根据实际业务需要进行岗位职责调整，适用于每一位职工，并非是针对来电人个人，鸿运承物业管理中心综合站务员A岗管理规定（试行）明确说明，新聘综合站务员A岗需具有大专学历，属工作需要并非学历歧视。 3.分中心与职工谈话属于正常工作谈话，旨在为职工详细讲解政策，情绪疏导，帮助落选人员进行安置，不存在“高频次施压”行为。 | X14: 经核实，与来电人所述情况存在出入：1.本次企业改革是根据《鸿运承物业管理中心综合站务员优化配置改革工作实施方案》、《鸿运承物业管理中心综合站务员A岗管理规定（试行）》等制度文件开展，综合站务员A岗岗位职责，管理方式均发生改变，现综合站务员A岗负责物业场站和人员的现场管理，以及辅助客运单位开展驾驶员安全叮嘱工作，与诉求中“岗位实质未变”存在出入。 2.企业根据实际业务需要进行岗位职责调整，适用于每一位职工，并非是针对来电人个人，鸿运承物业管理中心综合站务员A岗管理规定（试行）明确说明，新聘综合站务员A岗需具有大专学历，属工作需要并非学历歧视。 3.分中心与职工谈话属于正常工作谈话，旨在为职工详细讲解政策，情绪疏导，帮助落选人员进行安置，不存在“高频次施压”行为。 2025年12月23日上午9点47分左右电话与来电人回复，经过与来电人沟通，来电人对此表示不认可。 办理人：周健辉，鸿运承物业管理中心人力资源部，职务：一般管理； 审核人：高强；部门：鸿运承物业管理中心人力资源部；职务：中级管理。 | Y14: 2025年12月23日上午9点47分左右电话与来电人回复，经过与来电人沟通，来电人对此表示不认可。 | Z14: 无 | AA14: 无 | AB14: 经核实，与来电人所述情况存在出入：1.本次企业改革是根据《鸿运承物业管理中心综合站务员优化配置改革工作实施方案》、《鸿运承物业管理中心综合站务员A岗管理规定（试行）》等制度文件开展，综合站务员A岗岗位职责，管理方式均发生改变，现综合站务员A岗负责物业场站和人员的现场管理，以及辅助客运单位开展驾驶员安全叮嘱工作，与诉求中“岗位实质未变”存在出入。 2.企业根据实际业务需要进行岗位职责调整，适用于每一位职工，并非是针对来电人个人，鸿运承物业管理中心综合站务员A岗管理规定（试行）明确说明，新聘综合站务员A岗需具有大专学历，属工作需要并非学历歧视。 3.分中心与职工谈话属于正常工作谈话，旨在为职工详细讲解政策，情绪疏导，帮助落选人员进行安置，不存在“高频次施压”行为。 2025年12月23日上午9点47分左右电话与来电人回复，经过与来电人沟通，来电人对此表示不认可。 | AC14: 满意 | AD14: 个人 | AE14: 2025-12-21 15:18:26 | AF14: 1049051 | AG14: 劳动合同及用工管理 | AH14: 否 | AK14: =AG14&L14&M14 -> 劳动合同及用工管理工资及五险二金工资方面 | AP14: 10 | AQ14: 46023 | AR14: =IFERROR(LEFT(A14,FIND("（",A14)-1),A14) -> 网络-251222-008037 | AS14: =J14 -> 诉求 | AT14: =IF(MID(AR14,1,2)="热线",12345)+IF(MID(AR14,1,2)="网络",12345) -> 12345 | AU14: =IFERROR(LEFT(D14,FIND(" ",D14)-1),D14) -> 2025-12-22 | AV14: =P14 -> 人力资源部 | AW14: =Q14 -> 机关 | AX14: =H14 -> 工单来源：微信服务号，此工单内容为网民留言时填写的标题及原文。 ============================= 留言标题：投诉公交集团压榨员工留言原文：尊敬的北京公交鸿运承物业管理有限公司领导 / 上级主管部门： 您好！ 我是贵公司的一名老员工的家属。我怀着非常沉重和无奈的心情，向您反映公司近期对我爱人进行的不合理调岗降薪问题。 一、 本人基本情况与工作履历我爱你自进入公交系统工作，至今已有31年工龄。其中，她在运营一线担任调度员长达20多年，积累了丰富的管理经验和业务能力。2022年，转岗至北京公交鸿运承物业管理有限公司，担任综合站务员A岗，至今已在该岗位稳定工作3年。 二、 投诉事由：不合理的“岗变薪变”与学历歧视近期，公司以持有“红头文件”为由，突然要求综合站务员A岗必须具备大专学历，并以此为由要求我爱人转岗降薪。我认为这一决定极不合理，理由如下： 1. 岗位实质未变，能力完全胜任：目前的综合站务员A岗，其岗位职责与我爱人过去三年所从事的工作基本一致。我爱人在公交系统工作31年，拥有20多年调度经验和3年A岗实操经验，我爱人的业务能力和工作表现完全能够胜任当前岗位。公司在我爱人已熟练掌握岗位技能的情况下，突然以“学历”卡人，属于典型的形式主义，忽视了员工的实际工作能力。​2. 临近退休，此举缺乏人文关怀：我爱人距离法定退休年龄仅剩两年多。在企业工作了大半辈子，临近退休却面临如此大幅度的降薪，这对我爱人的生活和精神造成了巨大打击。公司的这种做法，严重违背了《劳动合同法》中关于“在本单位连续工作满十五年且距法定退休年龄不足五年的，用人单位不得依照本法第四十条、第四十一条的规定解除劳动合同”的精神，虽然公司未直接解除合同，但通过降薪逼迫员工离职，性质同样恶劣。 三、 协商过程中的不公待遇在与公司协商过程中，公司给出了四项安置方案，实则是“霸王条款”： 1. 转岗至综合站务员C岗： 工资从原A岗的（岗资3700+绩效4720）降至（岗资3100+绩效2720），降幅超过30%，这是我无法接受的。​2. 转岗至巡检员： 同样面临降薪。​3. 买断工龄。​4. 如不选择以上方案，则视为“下岗代工”。 由于我爱人拒绝签字同意这种不合理的降薪，公司相关人员频繁找我爱人“约谈”。这种高频次的约谈已经严重干扰了我爱人的正常工作和生活，导致我爱人精神压力巨大，身心状态极差。 四、 诉求综上所述，我恳请公司： 1. 立即停止这种针对老员工的不合理调岗降薪行为，尊重我31年的工作贡献和实际业务能力。​2. 维持我爱人目前的综合站务员A岗待遇，直至退休。​3. 停止高频次的施压约谈，给老员工一个安稳的工作环境。 我希望公司能从实际出发，妥善解决我爱人的问题，不要让一名即将退休的老员工寒心。 此致敬礼 市民填写的详细地址为：区：朝阳区街道：不详详细地址：北京市公共交通有限公司鸿运城物业中心 | AY14: =AG14 -> 劳动合同及用工管理 | AZ14: 是 | BA14: 是 | BB14: 否 | BC14: 七有五性,公正性 | BD14: =U14 -> 结束 | BE14: =IFERROR(LEFT(T14,FIND(" ",T14)-1),T14) -> 2025-12-27 | BF14: 劳动人员调配及薪酬 （公开选聘综A岗-学历问题）同人同诉 | BG14: 人力资源部 | BH14: 机关 | BL14: =IF(BG14="物管行政部","侯旭、郑楠",IF(BG14="安保部","张耕",IF(BG14="工程设备部","华菲",IF(BG14="人力资源部","成琦",IF(BG14="党委工作部","阎鑫雨",IF(BG14="餐饮服务部","赵弘晨",IF(BG14="工会","郑欣",IF(BG14="办公室","董娜",""))))))))&IF(BG14="纪检部","黄倩",IF(BG14="信息管理部","蔡浩然","")) -> 成琦 | BM14: 未主动剔除 | BP14: 政策类 | BQ14: 同人同诉：网络-251222-008037、网络-251223-037876 | BR14: 是 | BV14: =MID(AR14,1,16) -> 网络-251222-008037 | BW14: 七有五性,劳有所得 | BX14: =IF(COUNTIF(BV:BV,BV14)=1,"否","是") -> 否 | BY14: =MID(AR14,18,1) | CG14: =VLOOKUP(AR14,[1]市民意见信息导出!$AI$2:$AK$392,3,FALSE()) -> 结束 | CH14: =VLOOKUP(BV14,[2]Sheet1!$C$2:$AC$99,2,FALSE()) -> #N/A
A15: 热线-251222-022648（2个附件） | B15: 2025-12-22 11:12:47 | C15: 2025-12-22 11:32:06 | D15: 2025-12-22 11:33:40 | E15: 姜长明女士 | F15: 女 | G15: 手机,15210100103; | H15: 市民反映，自己是在北京公交集团的下属二级单位鸿运承物业管理中心职工，属于公交集团的下属二级单位，被所述下级公司恶意调岗，也向鸿运承物业管理中心公司的人力资源经理高强反馈过，公司承认是没有经过公交集团文件下发处理的，说沟通文件下发后给出回复，现在既没有回复，还直接没有任何排岗排班，市民现在岗位都是北京公交集团直接下发确认的岗位，都有红头文件，也从2025年3月开始变相调岗三次了，希望公交集团负责的领导给予处理回复，因为本次调岗是公交集团下属二级单位调岗操作，并不是公交集团进行处理的，故希望公交集团负责领导给出回复，姓名：姜长明，来电反映北京公交集团下属单位恶意调岗问题。 | I15: 是 | J15: 诉求 | K15: 人力资源部（人力资源发展中心） | L15: 工资及五险二金 | M15: 工资方面 | N15: 鸿运承物业管理中心 | O15: 凌家庙分中心 | P15: 人力资源部 | Q15: 凌家庙分中心 | R15: 2025-12-29 23:59:59 | S15: 2025-12-25 | T15: 2025-12-27 08:59:59 | U15: 结束 | V15: 1 | W15: 经核实，与来电人所述情况存在出入。来电人姜长明为我单位凌家庙分中心职工，其此前并未转岗，不涉及来电人所述的恶意调岗问题。本次企业改革是根据《鸿运承物业管理中心综合站务员优化配置改革工作实施方案》、《鸿运承物业管理中心综合站务员A岗管理规定（试行）》等制度文件开展，我单位为落选的原综A人员提供4类转岗安置方案。此前我单位凌家庙分中心于2025年11月27日、12月11日以及22日多次与来电人进行面对面的沟通，来电人均表示坚决拒绝调整A岗安置工作。 | X15: 经核实，与来电人所述情况存在出入。来电人姜长明为我单位凌家庙分中心职工，其此前并未转岗，不涉及来电人所述的恶意调岗问题。本次企业改革是根据《鸿运承物业管理中心综合站务员优化配置改革工作实施方案》、《鸿运承物业管理中心综合站务员A岗管理规定（试行）》等制度文件开展，我单位为落选的原综A人员提供4类转岗安置方案。此前我单位凌家庙分中心于2025年11月27日、12月11日以及22日多次与来电人进行面对面的沟通，来电人均表示坚决拒绝调整A岗安置工作。 接到诉求后，于2025年12月25日10点01分电话回复来电人，来电人表示已知晓后挂断电话，为确保来电人知晓政策，故我单位再次通过短信形式告知来电人办理结果。 办理人：王跃，鸿运承物业管理中心凌家庙分中心，职务：一般管理； 审核人：高强；部门：鸿运承物业管理中心人力资源部；职务：中级管理。 | Y15: 接到诉求后，于2025年12月25日10点01分电话回复来电人，来电人表示已知晓后挂断电话，为确保来电人知晓政策，故我单位再次通过短信形式告知来电人办理结果。 | Z15: 无 | AA15: 无 | AB15: 经核实，与来电人所述情况存在出入。来电人姜长明为我单位凌家庙分中心职工，其此前并未转岗，不涉及来电人所述的恶意调岗问题。本次企业改革是根据《鸿运承物业管理中心综合站务员优化配置改革工作实施方案》、《鸿运承物业管理中心综合站务员A岗管理规定（试行）》等制度文件开展，我单位为落选的原综A人员提供4类转岗安置方案。此前我单位凌家庙分中心于2025年11月27日、12月11日以及22日多次与来电人进行面对面的沟通，来电人均表示坚决拒绝调整A岗安置工作。 接到诉求后，于2025年12月25日10点01分电话回复来电人，来电人表示已知晓后挂断电话，为确保来电人知晓政策，故我单位再次通过短信形式告知来电人办理结果。 | AC15: 满意 | AD15: 个人 | AE15: 2025-12-22 11:03:19 | AF15: 1862108387 | AG15: 运营调度 | AH15: 否 | AK15: =AG15&L15&M15 -> 运营调度工资及五险二金工资方面 | AP15: 11 | AQ15: 46023 | AR15: =IFERROR(LEFT(A15,FIND("（",A15)-1),A15) -> 热线-251222-022648 | AS15: =J15 -> 诉求 | AT15: =IF(MID(AR15,1,2)="热线",12345)+IF(MID(AR15,1,2)="网络",12345) -> 12345 | AU15: =IFERROR(LEFT(D15,FIND(" ",D15)-1),D15) -> 2025-12-22 | AV15: =P15 -> 人力资源部 | AW15: =Q15 -> 凌家庙分中心 | AX15: =H15 -> 市民反映，自己是在北京公交集团的下属二级单位鸿运承物业管理中心职工，属于公交集团的下属二级单位，被所述下级公司恶意调岗，也向鸿运承物业管理中心公司的人力资源经理高强反馈过，公司承认是没有经过公交集团文件下发处理的，说沟通文件下发后给出回复，现在既没有回复，还直接没有任何排岗排班，市民现在岗位都是北京公交集团直接下发确认的岗位，都有红头文件，也从2025年3月开始变相调岗三次了，希望公交集团负责的领导给予处理回复，因为本次调岗是公交集团下属二级单位调岗操作，并不是公交集团进行处理的，故希望公交集团负责领导给出回复，姓名：姜长明，来电反映北京公交集团下属单位恶意调岗问题。 | AY15: =AG15 -> 运营调度 | AZ15: 是 | BA15: 是 | BB15: 否 | BC15: 七有五性,公正性 | BD15: =U15 -> 结束 | BE15: =IFERROR(LEFT(T15,FIND(" ",T15)-1),T15) -> 2025-12-27 | BF15: 劳动人员调配及薪酬 （综A岗调整） 多渠道同人同诉 | BG15: 人力资源部 | BH15: 凌家庙分中心 | BL15: =IF(BG15="物管行政部","侯旭、郑楠",IF(BG15="安保部","张耕",IF(BG15="工程设备部","华菲",IF(BG15="人力资源部","成琦",IF(BG15="党委工作部","阎鑫雨",IF(BG15="餐饮服务部","赵弘晨",IF(BG15="工会","郑欣",IF(BG15="办公室","董娜",""))))))))&IF(BG15="纪检部","黄倩",IF(BG15="信息管理部","蔡浩然","")) -> 成琦 | BM15: 未主动剔除 | BP15: 政策类 | BQ15: 综A公开招聘，针对政策条件不认可。（同人同诉多渠道）：GJ-PHONE-20251222-0767、热线-251222-022648 | BR15: 是 | BS15: 先96166后12345 | BV15: =MID(AR15,1,16) -> 热线-251222-022648 | BW15: 七有五性,便利性 | BX15: =IF(COUNTIF(BV:BV,BV15)=1,"否","是") -> 否 | BY15: =MID(AR15,18,1) | CG15: =VLOOKUP(AR15,[1]市民意见信息导出!$AI$2:$AK$392,3,FALSE()) -> 结束 | CH15: =VLOOKUP(BV15,[2]Sheet1!$C$2:$AC$99,2,FALSE()) -> #N/A
A16: 热线-251222-060978（1个附件） | B16: 2025-12-22 17:13:13 | C16: 2025-12-22 17:21:15 | D16: 2025-12-22 17:25:24 | E16: 何威涛女士 | F16: 女 | G16: 手机,13520598546; | H16: 市民反映，自己是肢体四级残疾人，一直在北京公交集团鸿运承物业九龙分中心工作，属于北京公交集团有限公司，今年49岁，是综合站务A岗，还有不到1年退休，之前因自己学历不够单位不让自己报名乘务巡查员，现在告知从1月15日起将对自己执行C岗工资，直降2600元，自己同意但是没有签字，期间劳人部门及工会主席，共给自己打9次电话及三次面谈，导致自己精神压力大现在患有焦虑症，姓名：何威涛， 希望单位不要再因此事联系自己，给自己造成精神压力导致病情加重，来电反映希望单位领导不要再给自己施加压力导致病情加重。注：另一问题见热线-251222-062831 | I16: 是 | J16: 其他 | K16: 人力资源部（人力资源发展中心） | L16: 人力资源方面其他问题 | M16: 人力资源方面补充内容 | N16: 鸿运承物业管理中心 | O16: 九龙分中心 | P16: 人力资源部 | Q16: 九龙分中心 | R16: 2025-12-29 23:59:59 | S16: 2025-12-23 | T16: 2025-12-27 08:59:59 | U16: 结束 | V16: 0 | W16: 接到职工投诉九龙分中心高度重视，立即核实情况。何威涛明春苑场站职工，按鸿运承物业管理中心综合站务员优化配置改革工作实施方案，对职工进行面对面告知。 | X16: 对以上内容于2025年12月23日下午15点进行电话回复，对以上问题进行回复，职工表示基本满意。 | Y16: 无 | Z16: 无 | AA16: 无 | AB16: 接到职工投诉九龙分中心高度重视，立即核实情况。何威涛明春苑场站职工，按鸿运承物业管理中心综合站务员优化配置改革工作实施方案，对职工进行面对面告知。对以上内容于2025年12月23日下午15点进行电话回复，对以上问题进行回复，职工表示基本满意。 | AC16: 满意 | AD16: 个人 | AE16: 2025-12-22 16:51:03 | AF16: 1741937714 | AG16: 劳动合同及用工管理 | AH16: 否 | AK16: =AG16&L16&M16 -> 劳动合同及用工管理人力资源方面其他问题人力资源方面补充内容 | AP16: 12 | AQ16: 46023 | AR16: =IFERROR(LEFT(A16,FIND("（",A16)-1),A16) -> 热线-251222-060978 | AS16: =J16 -> 其他 | AT16: =IF(MID(AR16,1,2)="热线",12345)+IF(MID(AR16,1,2)="网络",12345) -> 12345 | AU16: =IFERROR(LEFT(D16,FIND(" ",D16)-1),D16) -> 2025-12-22 | AV16: =P16 -> 人力资源部 | AW16: =Q16 -> 九龙分中心 | AX16: =H16 -> 市民反映，自己是肢体四级残疾人，一直在北京公交集团鸿运承物业九龙分中心工作，属于北京公交集团有限公司，今年49岁，是综合站务A岗，还有不到1年退休，之前因自己学历不够单位不让自己报名乘务巡查员，现在告知从1月15日起将对自己执行C岗工资，直降2600元，自己同意但是没有签字，期间劳人部门及工会主席，共给自己打9次电话及三次面谈，导致自己精神压力大现在患有焦虑症，姓名：何威涛， 希望单位不要再因此事联系自己，给自己造成精神压力导致病情加重，来电反映希望单位领导不要再给自己施加压力导致病情加重。注：另一问题见热线-251222-062831 | AY16: =AG16 -> 劳动合同及用工管理 | AZ16: 是 | BA16: 是 | BB16: 否 | BC16: 七有五性,公正性 | BD16: =U16 -> 结束 | BE16: =IFERROR(LEFT(T16,FIND(" ",T16)-1),T16) -> 2025-12-27 | BF16: 劳动人员调配及薪酬 （综A岗调整） 多渠道同人同诉 | BG16: 人力资源部 | BH16: 九龙分中心 | BL16: =IF(BG16="物管行政部","侯旭、郑楠",IF(BG16="安保部","张耕",IF(BG16="工程设备部","华菲",IF(BG16="人力资源部","成琦",IF(BG16="党委工作部","阎鑫雨",IF(BG16="餐饮服务部","赵弘晨",IF(BG16="工会","郑欣",IF(BG16="办公室","董娜",""))))))))&IF(BG16="纪检部","黄倩",IF(BG16="信息管理部","蔡浩然","")) -> 成琦 | BM16: 未主动剔除 | BP16: 政策类 | BV16: =MID(AR16,1,16) -> 热线-251222-060978 | BW16: 七有五性,劳有所得 | BX16: =IF(COUNTIF(BV:BV,BV16)=1,"否","是") -> 否 | BY16: =MID(AR16,18,1) | BZ16: 只评价响应率 | CE16: 1月 | CG16: =VLOOKUP(AR16,[1]市民意见信息导出!$AI$2:$AK$392,3,FALSE()) -> 结束 | CH16: =VLOOKUP(BV16,[2]Sheet1!$C$2:$AC$99,2,FALSE()) -> 1月
A17: 热线-251223-016057（2个附件） | B17: 2025-12-23 10:13:34 | C17: 2025-12-23 11:14:51 | D17: 2025-12-23 11:30:26 | E17: 胡亚静女士 | F17: 女 | G17: 手机,13716588237; | H17: 市民反映，市民是公交集团鸿运承物业管理中心的职工，鸿运承物业管理中心作为公交集团的下属二级单位，从2022年7月1日至2023年8月，鸿运承物业管理中心违背北京公交集团下发的红头文件内容，违法给部分综合站务员B岗C岗职工转为综合站务员A岗，这些转岗人员并没有履行集团公司下发红头文件的综合站务员A岗岗位职责等内容，直接目的是为了追求A岗工资，这番操作直接浪费了公交集团大量资金，从而使综合站务员A岗人员杂乱不堪，以至于综合站务员A岗人员称呼多样，如老综A，旧综A，原综A，后转综A，现在又弄出新综A，从今年3月份开始，鸿运承在没有任何集团下发文件的前提下，把违规转岗的A岗职工保护起来，反而针对性给受红头文件保护的职工恶意调岗，共进行三次恶意调岗，性质特别恶劣，致使被针对职工，身心收到严重创伤，11月27日鸿运承人力资源部经理和工会主席，都承认此次改革是在没有集团公司相关书面文件前提下进行的，在我们坚持一切以劳动法为根基的基础上，他们承诺去和集团领导协商获取有效文件，并且还承诺一定会给职工明确答复，有录音为证，但现在在没有任何答复的前提下，12月26日已经停止排班，已下发排班表，我们职工真心不明白，身为下属二级单位领导，身为共产党干部，怎么会做出霸权主义的事情，敬请北京公交集团相关领导给予职工明确回复，职工姓名：胡亚静，自己来到了公交集团，但没有公交集团的人员来处理问题，来电反映敬请北京公交集团相关领导给予职工明确回复的问题。 | I17: 是 | J17: 诉求 | K17: 人力资源部（人力资源发展中心） | L17: 工资及五险二金 | M17: 工资方面 | N17: 鸿运承物业管理中心 | O17: 凌家庙分中心 | P17: 人力资源部 | Q17: 凌家庙分中心 | R17: 2025-12-30 23:59:59 | S17: 2025-12-25 | T17: 2025-12-28 08:59:59 | U17: 结束 | V17: 1 | W17: 经核实，与来电人所述情况存在出入。来电人胡亚静为我单位凌家庙分中心职工，此前我单位并未对来电人进行转岗，不涉及来电人所述的恶意调岗问题。本次企业改革是根据《鸿运承物业管理中心综合站务员优化配置改革工作实施方案》、《鸿运承物业管理中心综合站务员A岗管理规定（试行）》等制度文件开展，我单位为落选的原综A人员提供4类转岗安置方案。此前我单位凌家庙分中心于2025年11月27日、12月11日以及22日多次与来电人进行面对面的沟通，来电人均表示坚决拒绝调整A岗安置工作。 | X17: 经核实，与来电人所述情况存在出入。来电人胡亚静为我单位凌家庙分中心职工，此前我单位并未对来电人进行转岗，不涉及来电人所述的恶意调岗问题。本次企业改革是根据《鸿运承物业管理中心综合站务员优化配置改革工作实施方案》、《鸿运承物业管理中心综合站务员A岗管理规定（试行）》等制度文件开展，我单位为落选的原综A人员提供4类转岗安置方案。此前我单位凌家庙分中心于2025年11月27日、12月11日以及22日多次与来电人进行面对面的沟通，来电人均表示坚决拒绝调整A岗安置工作。 接到诉求后，我单位凌家庙分中心于2025年12月25日9点53分电话回复来电人，来电人将电话挂断，故我单位再次通过短信形式告知来电人办理结果。 办理人：王跃，鸿运承物业管理中心凌家庙分中心，职务：一般管理； 审核人：高强；部门：鸿运承物业管理中心人力资源部；职务：中级管理。 | Y17: 接到诉求后，我单位凌家庙分中心于2025年12月25日9点53分电话回复来电人，来电人将电话挂断，故我单位再次通过短信形式告知来电人办理结果。 | Z17: 无 | AA17: 无 | AB17: 经核实，与来电人所述情况存在出入。来电人胡亚静为我单位凌家庙分中心职工，此前我单位并未对来电人进行转岗，不涉及来电人所述的恶意调岗问题。本次企业改革是根据《鸿运承物业管理中心综合站务员优化配置改革工作实施方案》、《鸿运承物业管理中心综合站务员A岗管理规定（试行）》等制度文件开展，我单位为落选的原综A人员提供4类转岗安置方案。此前我单位凌家庙分中心于2025年11月27日、12月11日以及22日多次与来电人进行面对面的沟通，来电人均表示坚决拒绝调整A岗安置工作。 接到诉求后，我单位凌家庙分中心于2025年12月25日9点53分电话回复来电人，来电人将电话挂断，故我单位再次通过短信形式告知来电人办理结果。 | AC17: 满意 | AD17: 个人 | AE17: 2025-12-23 10:11:21 | AF17: 1862108387 | AG17: 运营调度 | AH17: 否 | AK17: =AG17&L17&M17 -> 运营调度工资及五险二金工资方面 | AP17: 13 | AQ17: 46023 | AR17: =IFERROR(LEFT(A17,FIND("（",A17)-1),A17) -> 热线-251223-016057 | AS17: =J17 -> 诉求 | AT17: =IF(MID(AR17,1,2)="热线",12345)+IF(MID(AR17,1,2)="网络",12345) -> 12345 | AU17: =IFERROR(LEFT(D17,FIND(" ",D17)-1),D17) -> 2025-12-23 | AV17: =P17 -> 人力资源部 | AW17: =Q17 -> 凌家庙分中心 | AX17: =H17 -> 市民反映，市民是公交集团鸿运承物业管理中心的职工，鸿运承物业管理中心作为公交集团的下属二级单位，从2022年7月1日至2023年8月，鸿运承物业管理中心违背北京公交集团下发的红头文件内容，违法给部分综合站务员B岗C岗职工转为综合站务员A岗，这些转岗人员并没有履行集团公司下发红头文件的综合站务员A岗岗位职责等内容，直接目的是为了追求A岗工资，这番操作直接浪费了公交集团大量资金，从而使综合站务员A岗人员杂乱不堪，以至于综合站务员A岗人员称呼多样，如老综A，旧综A，原综A，后转综A，现在又弄出新综A，从今年3月份开始，鸿运承在没有任何集团下发文件的前提下，把违规转岗的A岗职工保护起来，反而针对性给受红头文件保护的职工恶意调岗，共进行三次恶意调岗，性质特别恶劣，致使被针对职工，身心收到严重创伤，11月27日鸿运承人力资源部经理和工会主席，都承认此次改革是在没有集团公司相关书面文件前提下进行的，在我们坚持一切以劳动法为根基的基础上，他们承诺去和集团领导协商获取有效文件，并且还承诺一定会给职工明确答复，有录音为证，但现在在没有任何答复的前提下，12月26日已经停止排班，已下发排班表，我们职工真心不明白，身为下属二级单位领导，身为共产党干部，怎么会做出霸权主义的事情，敬请北京公交集团相关领导给予职工明确回复，职工姓名：胡亚静，自己来到了公交集团，但没有公交集团的人员来处理问题，来电反映敬请北京公交集团相关领导给予职工明确回复的问题。 | AY17: =AG17 -> 运营调度 | AZ17: 是 | BA17: 是 | BB17: 否 | BC17: 七有五性,公正性 | BD17: =U17 -> 结束 | BE17: =IFERROR(LEFT(T17,FIND(" ",T17)-1),T17) -> 2025-12-28 | BF17: 劳动人员调配及薪酬 （公开选聘综A岗-学历问题） 多渠道同人同诉 多次 | BG17: 人力资源部 | BH17: 凌家庙分中心 | BL17: =IF(BG17="物管行政部","侯旭、郑楠",IF(BG17="安保部","张耕",IF(BG17="工程设备部","华菲",IF(BG17="人力资源部","成琦",IF(BG17="党委工作部","阎鑫雨",IF(BG17="餐饮服务部","赵弘晨",IF(BG17="工会","郑欣",IF(BG17="办公室","董娜",""))))))))&IF(BG17="纪检部","黄倩",IF(BG17="信息管理部","蔡浩然","")) -> 成琦 | BM17: 未主动剔除 | BP17: 政策类 | BQ17: 综A公开招聘，针对政策条件不认可。（同人同诉）：热线-250611-039775、热线-250611-059472-1、热线-250618-048072-1、热线-250708-035022、热线-251222-018664、热线-251223-016057 | BR17: 是 | BS17: 先96166后12345 | BV17: =MID(AR17,1,16) -> 热线-251223-016057 | BW17: 七有五性,便利性 | BX17: =IF(COUNTIF(BV:BV,BV17)=1,"否","是") -> 否 | BY17: =MID(AR17,18,1) | CG17: =VLOOKUP(AR17,[1]市民意见信息导出!$AI$2:$AK$392,3,FALSE()) -> 结束 | CH17: =VLOOKUP(BV17,[2]Sheet1!$C$2:$AC$99,2,FALSE()) -> #N/A
A18: 网络-251223-037876（2个附件） | B18: 2025-12-23 14:06:32 | C18: 2025-12-23 14:10:21 | D18: 2025-12-23 14:27:48 | E18: 倪大伟 | F18: 男 | G18: 手机,13681321121; | H18: 工单来源：微信服务号，此工单内容为网民留言时填写的标题及原文。 ============================= 留言标题：北京公交鸿运承物业管理有限公司不合理调岗降薪的投诉信留言原文： 尊敬的北京公共交通控股集团有限公司领导： 您好！ 我是贵公司下属北京公交鸿运承物业管理有限公司一名老员工的家属，怀着无奈与失望的心情，向您反映公司针对我爱人的不合理调岗降薪问题。 一、员工基本情况与工作履历 我爱人在公交系统工作长达31年，其中在运营一线担任调度员20多年，积累了丰富管理经验与业务能力。2022年转岗至北京公交鸿运承物业管理有限公司，任综合站务员A岗，至今已稳定工作3年。 二、投诉事由 （一）不合理的“岗变薪变”与学历歧视 1. 岗位实质与能力匹配：当前综合站务员A岗的岗位职责与我爱人过去3年从事的工作基本一致。她拥有31年公交系统工作经验，其中包括20多年调度经验和3年A岗实操经验，完全能够胜任岗位。公司此时以“学历”为由卡人，属于形式主义，忽视员工实际工作能力。​2. 临近退休缺乏人文关怀：我爱人距法定退休年龄仅剩两年多，在企业奉献大半辈子，临近退休却面临大幅降薪，这对其生活和精神造成巨大打击。公司此举违背了《劳动合同法》第四十二条规定，即“在本单位连续工作满十五年且距法定退休年龄不足五年的，用人单位不得依照本法第四十条、第四十一条的规定解除劳动合同”。虽公司未直接解除合同，但通过降薪逼迫员工离职，性质恶劣。 （二）协商过程中的不公待遇 在与公司协商过程中，公司给出的四项安置方案实为“霸王条款”： 1. 转岗至综合站务员C岗：工资从原A岗的（岗资3700 + 绩效4720）降至（岗资3100 + 绩效2720），降幅超30%，难以接受。​2. 转岗至巡检员：同样面临降薪。​3. 买断工龄。​4. **如不选择以上方案，则视为“下岗代工”。 因我爱人拒绝签字同意不合理降薪，公司相关人员频繁“约谈”，严重干扰其正常工作和生活，导致她精神压力巨大，身心状态极差。在录音中也可明确听到，我爱人明确表示不同意，但公司人员却歪曲事实，称其同意签字认可，这种行为极其不妥。 （三）内部反映无果 此前，我们已向北京公交鸿运承物业管理有限公司反映该问题，希望公司能重视员工权益，合理解决调岗降薪事宜。然而，公司反馈称其做法合理，并未对不合理之处进行纠正，这让我们深感失望。我们认为公司未能充分考虑员工实际情况和合法权益，处理方式有失公正。 三、诉求 综上所述，恳请贵集团： 1. 立即停止下属公司针对老员工的不合理调岗降薪行为，尊重我爱人31年的工作贡献和实际业务能力。​2. 督促北京公交鸿运承物业管理有限公司维持我爱人目前的综合站务员A岗待遇，直至退休。​3. 要求下属公司停止高频次的施压约谈，给予老员工安稳的工作环境。 希望贵集团能从实际出发，妥善解决问题，不要让为公交系统奉献多年的老员工寒心。 此致 敬礼！ 市民填写的详细地址为：区、街道：丰台区卢沟桥街道详细地址：北京公交集团 | I18: 是 | J18: 诉求 | K18: 人力资源部（人力资源发展中心） | L18: 工资及五险二金 | M18: 工资方面 | N18: 鸿运承物业管理中心 | O18: 单店分中心 | P18: 人力资源部 | Q18: 单店分中心 | R18: 2025-12-30 23:59:59 | S18: 2025-12-25 | T18: 2025-12-28 08:59:59 | U18: 结束 | V18: 1 | W18: 经核实，来电人为我单位职工家属，与来电人所述情况存在出入。首先，本次企业改革是根据《鸿运承物业管理中心综合站务员优化配置改革工作实施方案》、《鸿运承物业管理中心综合站务员A岗管理规定（试行）》等制度文件开展，综合站务员A岗岗位职责，管理方式均发生改变，现综合站务员A岗负责物业场站和人员的现场管理，以及辅助客运单位开展驾驶员安全叮嘱工作，与诉求中“岗位实质未变”存在出入。 企业根据实际业务需要进行岗位职责调整，适用于每一位职工，并非是针对来电人家属个人，鸿运承物业管理中心综合站务员A岗管理规定（试行）明确说明，新聘综合站务员A岗需具有大专学历，属工作需要并非学历歧视。 分中心与职工谈话属于正常工作谈话，旨在为职工详细讲解政策，情绪疏导，帮助落选人员进行安置，不存在“高频次施压”行为。 | X18: 经核实，来电人为我单位职工家属，与来电人所述情况存在出入。首先，本次企业改革是根据《鸿运承物业管理中心综合站务员优化配置改革工作实施方案》、《鸿运承物业管理中心综合站务员A岗管理规定（试行）》等制度文件开展，综合站务员A岗岗位职责，管理方式均发生改变，现综合站务员A岗负责物业场站和人员的现场管理，以及辅助客运单位开展驾驶员安全叮嘱工作，与诉求中“岗位实质未变”存在出入。 企业根据实际业务需要进行岗位职责调整，适用于每一位职工，并非是针对来电人家属个人，鸿运承物业管理中心综合站务员A岗管理规定（试行）明确说明，新聘综合站务员A岗需具有大专学历，属工作需要并非学历歧视。 分中心与职工谈话属于正常工作谈话，旨在为职工详细讲解政策，情绪疏导，帮助落选人员进行安置，不存在“高频次施压”行为。 接到本条投诉后，分中心于2025年12月25日下午13点56分左右电话回复，来电人未听完回复就挂断电话，后我单位又以短信形式再次与来电人进行回复。 办理人：杨飞，部门：鸿运承物业管理中心单店分中心，职务：一般管理； 审核人：高强；部门：鸿运承物业管理中心人力资源部；职务：中级管理。 | Y18: 接到本条投诉后，分中心于2025年12月25日下午13点56分左右电话回复，来电人未听完回复就挂断电话，后我单位又以短信形式再次与来电人进行回复。 | Z18: 无 | AA18: 无 | AB18: 经核实，来电人为我单位职工家属，与来电人所述情况存在出入。首先，本次企业改革是根据《鸿运承物业管理中心综合站务员优化配置改革工作实施方案》、《鸿运承物业管理中心综合站务员A岗管理规定（试行）》等制度文件开展，综合站务员A岗岗位职责，管理方式均发生改变，现综合站务员A岗负责物业场站和人员的现场管理，以及辅助客运单位开展驾驶员安全叮嘱工作，与诉求中“岗位实质未变”存在出入。 企业根据实际业务需要进行岗位职责调整，适用于每一位职工，并非是针对来电人家属个人，鸿运承物业管理中心综合站务员A岗管理规定（试行）明确说明，新聘综合站务员A岗需具有大专学历，属工作需要并非学历歧视。 分中心与职工谈话属于正常工作谈话，旨在为职工详细讲解政策，情绪疏导，帮助落选人员进行安置，不存在“高频次施压”行为。 接到本条投诉后，分中心于2025年12月25日下午13点56分左右电话回复，来电人未听完回复就挂断电话，后我单位又以短信形式再次与来电人进行回复。 | AC18: 满意 | AD18: 个人 | AE18: 2025-12-23 11:41:15 | AF18: 1741937706 | AG18: 劳动合同及用工管理 | AH18: 否 | AK18: =AG18&L18&M18 -> 劳动合同及用工管理工资及五险二金工资方面 | AP18: 14 | AQ18: 46023 | AR18: =IFERROR(LEFT(A18,FIND("（",A18)-1),A18) -> 网络-251223-037876 | AS18: =J18 -> 诉求 | AT18: =IF(MID(AR18,1,2)="热线",12345)+IF(MID(AR18,1,2)="网络",12345) -> 12345 | AU18: =IFERROR(LEFT(D18,FIND(" ",D18)-1),D18) -> 2025-12-23 | AV18: =P18 -> 人力资源部 | AW18: =Q18 -> 单店分中心 | AX18: =H18 -> 工单来源：微信服务号，此工单内容为网民留言时填写的标题及原文。 ============================= 留言标题：北京公交鸿运承物业管理有限公司不合理调岗降薪的投诉信留言原文： 尊敬的北京公共交通控股集团有限公司领导： 您好！ 我是贵公司下属北京公交鸿运承物业管理有限公司一名老员工的家属，怀着无奈与失望的心情，向您反映公司针对我爱人的不合理调岗降薪问题。 一、员工基本情况与工作履历 我爱人在公交系统工作长达31年，其中在运营一线担任调度员20多年，积累了丰富管理经验与业务能力。2022年转岗至北京公交鸿运承物业管理有限公司，任综合站务员A岗，至今已稳定工作3年。 二、投诉事由 （一）不合理的“岗变薪变”与学历歧视 1. 岗位实质与能力匹配：当前综合站务员A岗的岗位职责与我爱人过去3年从事的工作基本一致。她拥有31年公交系统工作经验，其中包括20多年调度经验和3年A岗实操经验，完全能够胜任岗位。公司此时以“学历”为由卡人，属于形式主义，忽视员工实际工作能力。​2. 临近退休缺乏人文关怀：我爱人距法定退休年龄仅剩两年多，在企业奉献大半辈子，临近退休却面临大幅降薪，这对其生活和精神造成巨大打击。公司此举违背了《劳动合同法》第四十二条规定，即“在本单位连续工作满十五年且距法定退休年龄不足五年的，用人单位不得依照本法第四十条、第四十一条的规定解除劳动合同”。虽公司未直接解除合同，但通过降薪逼迫员工离职，性质恶劣。 （二）协商过程中的不公待遇 在与公司协商过程中，公司给出的四项安置方案实为“霸王条款”： 1. 转岗至综合站务员C岗：工资从原A岗的（岗资3700 + 绩效4720）降至（岗资3100 + 绩效2720），降幅超30%，难以接受。​2. 转岗至巡检员：同样面临降薪。​3. 买断工龄。​4. **如不选择以上方案，则视为“下岗代工”。 因我爱人拒绝签字同意不合理降薪，公司相关人员频繁“约谈”，严重干扰其正常工作和生活，导致她精神压力巨大，身心状态极差。在录音中也可明确听到，我爱人明确表示不同意，但公司人员却歪曲事实，称其同意签字认可，这种行为极其不妥。 （三）内部反映无果 此前，我们已向北京公交鸿运承物业管理有限公司反映该问题，希望公司能重视员工权益，合理解决调岗降薪事宜。然而，公司反馈称其做法合理，并未对不合理之处进行纠正，这让我们深感失望。我们认为公司未能充分考虑员工实际情况和合法权益，处理方式有失公正。 三、诉求 综上所述，恳请贵集团： 1. 立即停止下属公司针对老员工的不合理调岗降薪行为，尊重我爱人31年的工作贡献和实际业务能力。​2. 督促北京公交鸿运承物业管理有限公司维持我爱人目前的综合站务员A岗待遇，直至退休。​3. 要求下属公司停止高频次的施压约谈，给予老员工安稳的工作环境。 希望贵集团能从实际出发，妥善解决问题，不要让为公交系统奉献多年的老员工寒心。 此致 敬礼！ 市民填写的详细地址为：区、街道：丰台区卢沟桥街道详细地址：北京公交集团 | AY18: =AG18 -> 劳动合同及用工管理 | AZ18: 是 | BA18: 是 | BB18: 否 | BC18: 七有五性,公正性 | BD18: =U18 -> 结束 | BE18: =IFERROR(LEFT(T18,FIND(" ",T18)-1),T18) -> 2025-12-28 | BF18: 劳动人员调配及薪酬 （公开选聘综A岗-学历问题）同人同诉 | BG18: 人力资源部 | BH18: 单店分中心 | BL18: =IF(BG18="物管行政部","侯旭、郑楠",IF(BG18="安保部","张耕",IF(BG18="工程设备部","华菲",IF(BG18="人力资源部","成琦",IF(BG18="党委工作部","阎鑫雨",IF(BG18="餐饮服务部","赵弘晨",IF(BG18="工会","郑欣",IF(BG18="办公室","董娜",""))))))))&IF(BG18="纪检部","黄倩",IF(BG18="信息管理部","蔡浩然","")) -> 成琦 | BM18: 未主动剔除 | BP18: 政策类 | BQ18: 同人同诉：网络-251222-008037、网络-251223-037876 | BR18: 是 | BV18: =MID(AR18,1,16) -> 网络-251223-037876 | BW18: 七有五性,劳有所得 | BX18: =IF(COUNTIF(BV:BV,BV18)=1,"否","是") -> 否 | BY18: =MID(AR18,18,1) | BZ18: 只评价响应率 | CE18: 1月 | CG18: =VLOOKUP(AR18,[1]市民意见信息导出!$AI$2:$AK$392,3,FALSE()) -> 结束 | CH18: =VLOOKUP(BV18,[2]Sheet1!$C$2:$AC$99,2,FALSE()) -> 1月
A19: 网络-251223-042262-4 | B19: 2025-12-23 14:43:46 | C19: 2025-12-23 14:53:58 | D19: 2025-12-23 15:04:49 | E19: 高新生 | F19: 男 | G19: 手机,13717801036; | H19: 工单来源：微信服务号，此工单内容为网民留言时填写的标题及原文。 ============================= 留言标题：不雅.肮脏.懒政.失职的北京市599路公交车（当值随车保安和司机）留言原文：2025-12-16下午16：26本人在此车内，发现有许多区域肮脏.不雅.上座前还需本人自行清理（车号3628334），这又一次证明此车队人员不尽责；车队领导们不作为（书记王广宇13910701906；队长王璐女15910568188等数名责任人员）问题仍存在！急需整顿.治理.纠正和换人！望市民热线和上级职能部门做深入督查和惩处！还市民对北京市公共交道以信心！！！市民填写的详细地址为：区、街道：大兴区黄村镇详细地址：博兴六路公交场站，67834230/67656962。安服安保组织 鸿运承 | I19: 是 | J19: 诉求 | K19: 行车安全服务部 | L19: 企业政策问题 | M19: 调整服务规范 | N19: 鸿运承物业管理中心 | O19: 明月湾分中心 | P19: 物管行政部 | Q19: 明月湾分中心 | R19: 2025-12-30 23:59:59 | S19: 2025-12-24 | T19: 2025-12-28 08:59:59 | U19: 结束 | V19: 0 | W19: 您好，关于您反映问题的办理情况，鸿运承物业管理中心明月湾分中心现对您回复如下： | X19: 我分中心已于2025年12月24日上午10点52分对您进行电话回复。办理人：吴岩；部门：鸿运承物业管理中心明月湾分中心；职务；物管副主任。审核人：郑楠；部门：鸿运承物业管理中心物管行政部；职务：物管员。 | Y19: 高先生您好，599路公交车我们在泰和园三里场站进行洗车服务工作，您所述3628334号车，车辆运营中发现有许多区域肮脏、不雅、上座前还需您自行清理的问题，我们非常重视您的反馈，您提供的问题照片我们已收到，由于我们的工作没有做好，599路给您带来不好的乘车体验，实在是抱歉，高先生。该车辆回到泰和园三里场站后，在日常工作时段内，我们保洁员已对车内玻璃、座椅、内壁等部位的卫生进行了全面的清理，确保我们的出场车辆卫生符合企业标准。您反馈的问题我们已整改完毕，同时我们要求保洁员对599路所有运营车辆的卫生再次进行细化清理。我们对于运营车辆车内卫生的清洁工作是一直在做的，也从未停止，已经形成了长效的清洁机制，但有时候卫生清洁工作我们做的还有不尽人意之处，您多多谅解。 | Z19: 我们分中心及场站班组长再次与599路的保洁人员进行了沟通，日常工作中我们要把清洁质量做的更加细致，同时加强保洁员清洁技能的培训，熟练掌握清洁方法，确保给您带来一个干净、整洁的出行环境。 | AA19: 我们定期会召开车辆保洁专题会议，开展车辆卫生专项检查，日常工作中我们加大巡检力度，强化制度建设，不断提高管理水平。 | AB19: 欢迎您随时对我们的工作进行监督，感谢您提出宝贵意见，给您的出行带来的不便我们和您说声抱歉，谢谢您的支持与谅解。 | AC19: 满意 | AD19: 个人 | AE19: 2025-12-23 11:56:07 | AF19: 1741937713 | AG19: 服务 | AH19: 否 | AK19: =AG19&L19&M19 -> 服务企业政策问题调整服务规范 | AP19: 15 | AQ19: 46023 | AR19: =IFERROR(LEFT(A19,FIND("（",A19)-1),A19) -> 网络-251223-042262-4 | AS19: =J19 -> 诉求 | AT19: =IF(MID(AR19,1,2)="热线",12345)+IF(MID(AR19,1,2)="网络",12345) -> 12345 | AU19: =IFERROR(LEFT(D19,FIND(" ",D19)-1),D19) -> 2025-12-23 | AV19: =P19 -> 物管行政部 | AW19: =Q19 -> 明月湾分中心 | AX19: =H19 -> 工单来源：微信服务号，此工单内容为网民留言时填写的标题及原文。 ============================= 留言标题：不雅.肮脏.懒政.失职的北京市599路公交车（当值随车保安和司机）留言原文：2025-12-16下午16：26本人在此车内，发现有许多区域肮脏.不雅.上座前还需本人自行清理（车号3628334），这又一次证明此车队人员不尽责；车队领导们不作为（书记王广宇13910701906；队长王璐女15910568188等数名责任人员）问题仍存在！急需整顿.治理.纠正和换人！望市民热线和上级职能部门做深入督查和惩处！还市民对北京市公共交道以信心！！！市民填写的详细地址为：区、街道：大兴区黄村镇详细地址：博兴六路公交场站，67834230/67656962。安服安保组织 鸿运承 | AY19: =AG19 -> 服务 | AZ19: 否 | BA19: 否 | BB19: 否 | BC19: 七有五性,宜居性 | BD19: =U19 -> 结束 | BE19: =IFERROR(LEFT(T19,FIND(" ",T19)-1),T19) -> 2025-12-28 | BF19: 车辆卫生问题 （车内卫生、玻璃） | BG19: 物管行政部 | BH19: 明月湾分中心 | BL19: =IF(BG19="物管行政部","侯旭、郑楠",IF(BG19="安保部","张耕",IF(BG19="工程设备部","华菲",IF(BG19="人力资源部","成琦",IF(BG19="党委工作部","阎鑫雨",IF(BG19="餐饮服务部","赵弘晨",IF(BG19="工会","郑欣",IF(BG19="办公室","董娜",""))))))))&IF(BG19="纪检部","黄倩",IF(BG19="信息管理部","蔡浩然","")) -> 侯旭、郑楠 | BM19: 未主动剔除 | BP19: 业务类 | BQ19: 多渠道同人同诉：网络-251223-042262-4、热线-260105-038505-2、网络-260109-053098-1、GJ-PHONE-20260111-0012 | BR19: 是 | BS19: 先12345再96166 | BV19: =MID(AR19,1,16) -> 网络-251223-042262 | BW19: 七有五性,便利性 | BX19: =IF(COUNTIF(BV:BV,BV19)=1,"否","是") -> 否 | BY19: =MID(AR19,18,1) -> 4 | CG19: =VLOOKUP(AR19,[1]市民意见信息导出!$AI$2:$AK$392,3,FALSE()) -> 结束 | CH19: =VLOOKUP(BV19,[2]Sheet1!$C$2:$AC$99,2,FALSE()) -> #N/A
A20: 热线-251222-074443（1个附件） | B20: 2025-12-23 17:32:42 | C20: 2025-12-23 17:42:33 | D20: 2025-12-23 17:47:18 | E20: 樊女士 | F20: 女 | G20: 手机,13513266399; | H20: 市民反映，自己是公交集团（公司名称：北京公共交通控股（集团）有限公司，地址：西城区南礼士路44号）的员工，自己生育后回到公司，公司给自己安排的都是体力活，对此不认可，沟通后说让自己待岗三个月，每月1800元，来电反映公司安排工作不合理问题。工单流转：西城区分中心退回：经核实，诉求人反映北京公共交通控股（集团）有限公司鸿运承物业管理中心工作安排不合理的问题。市民表示其产假后返岗后在河北香河县工作，公司拟安排市民返回单位内部分配的B、C岗位或继续待岗，市民认为其市民身体情况不适宜B、C岗位，希望单位或上级单位能够重新考虑安排。经查，鸿运承物业管理中心上级单位为北京公共交通控股（集团）有限公司。工作人员告知市民希望与单位协商工作安排事宜属于单位内部管理问题，烦请市中心转上级单位北京公共交通控股（集团）有限公司进行协调。 | I20: 是 | J20: 诉求 | K20: 人力资源部（人力资源发展中心） | L20: 工资及五险二金 | M20: 工资方面 | N20: 鸿运承物业管理中心 | O20: 凌家庙分中心 | P20: 人力资源部 | Q20: 凌家庙分中心 | R20: 2025-12-30 23:59:59 | S20: 2025-12-25 | T20: 2025-12-28 08:59:59 | U20: 结束 | V20: 1 | W20: 经核实，来电人为我单位凌家庙分中心职工，与来电人所述情况存在出入。本次企业改革是根据《鸿运承物业管理中心综合站务员优化配置改革工作实施方案》、《鸿运承物业管理中心综合站务员A岗管理规定（试行）》等制度文件开展，我单位为落选的原综A人员提供4类转岗安置方案，并非直接安排B岗、C岗工作。且分中心于12月15日通过微信形式通知来电人可参与乘务巡检员竞聘，来电人未报名。12月22日凌家庙分中心相关领导及劳人员也与来电人进行面对面沟通。 | X20: 经核实，来电人为我单位凌家庙分中心职工，与来电人所述情况存在出入。本次企业改革是根据《鸿运承物业管理中心综合站务员优化配置改革工作实施方案》、《鸿运承物业管理中心综合站务员A岗管理规定（试行）》等制度文件开展，我单位为落选的原综A人员提供4类转岗安置方案，并非直接安排B岗、C岗工作。且分中心于12月15日通过微信形式通知来电人可参与乘务巡检员竞聘，来电人未报名。12月22日凌家庙分中心相关领导及劳人员也与来电人进行面对面沟通。 接到诉求后，我单位分中心于12月25日10点31分与来电人进行电话回复，经过与来电人沟通，来电人表示已知晓。 办理人：王跃，鸿运承物业管理中心凌家庙分中心，职务：一般管理； 审核人：高强；部门：鸿运承物业管理中心人力资源部；职务：中级管理。 | Y20: 接到诉求后，我单位分中心于12月25日10点31分与来电人进行电话回复，经过与来电人沟通，来电人表示已知晓。 | Z20: 无 | AA20: 无 | AB20: 经核实，来电人为我单位凌家庙分中心职工，与来电人所述情况存在出入。本次企业改革是根据《鸿运承物业管理中心综合站务员优化配置改革工作实施方案》、《鸿运承物业管理中心综合站务员A岗管理规定（试行）》等制度文件开展，我单位为落选的原综A人员提供4类转岗安置方案，并非直接安排B岗、C岗工作。且分中心于12月15日通过微信形式通知来电人可参与乘务巡检员竞聘，来电人未报名。12月22日凌家庙分中心相关领导及劳人员也与来电人进行面对面沟通。 接到诉求后，我单位分中心于12月25日10点31分与来电人进行电话回复，经过与来电人沟通，来电人表示已知晓。 | AC20: 满意 | AD20: 个人 | AE20: 2025-12-22 20:31:08 | AF20: 1862108387 | AG20: 劳动合同及用工管理 | AH20: 否 | AK20: =AG20&L20&M20 -> 劳动合同及用工管理工资及五险二金工资方面 | AP20: 16 | AQ20: 46023 | AR20: =IFERROR(LEFT(A20,FIND("（",A20)-1),A20) -> 热线-251222-074443 | AS20: =J20 -> 诉求 | AT20: =IF(MID(AR20,1,2)="热线",12345)+IF(MID(AR20,1,2)="网络",12345) -> 12345 | AU20: =IFERROR(LEFT(D20,FIND(" ",D20)-1),D20) -> 2025-12-23 | AV20: =P20 -> 人力资源部 | AW20: =Q20 -> 凌家庙分中心 | AX20: =H20 -> 市民反映，自己是公交集团（公司名称：北京公共交通控股（集团）有限公司，地址：西城区南礼士路44号）的员工，自己生育后回到公司，公司给自己安排的都是体力活，对此不认可，沟通后说让自己待岗三个月，每月1800元，来电反映公司安排工作不合理问题。工单流转：西城区分中心退回：经核实，诉求人反映北京公共交通控股（集团）有限公司鸿运承物业管理中心工作安排不合理的问题。市民表示其产假后返岗后在河北香河县工作，公司拟安排市民返回单位内部分配的B、C岗位或继续待岗，市民认为其市民身体情况不适宜B、C岗位，希望单位或上级单位能够重新考虑安排。经查，鸿运承物业管理中心上级单位为北京公共交通控股（集团）有限公司。工作人员告知市民希望与单位协商工作安排事宜属于单位内部管理问题，烦请市中心转上级单位北京公共交通控股（集团）有限公司进行协调。 | AY20: =AG20 -> 劳动合同及用工管理 | AZ20: 是 | BA20: 是 | BB20: 否 | BC20: 七有五性,公正性 | BD20: =U20 -> 结束 | BE20: =IFERROR(LEFT(T20,FIND(" ",T20)-1),T20) -> 2025-12-28 | BF20: 劳动人员调配及薪酬 （综A岗-产后复岗） | BG20: 人力资源部 | BH20: 凌家庙分中心 | BL20: =IF(BG20="物管行政部","侯旭、郑楠",IF(BG20="安保部","张耕",IF(BG20="工程设备部","华菲",IF(BG20="人力资源部","成琦",IF(BG20="党委工作部","阎鑫雨",IF(BG20="餐饮服务部","赵弘晨",IF(BG20="工会","郑欣",IF(BG20="办公室","董娜",""))))))))&IF(BG20="纪检部","黄倩",IF(BG20="信息管理部","蔡浩然","")) -> 成琦 | BM20: 未主动剔除 | BP20: 政策类 | BV20: =MID(AR20,1,16) -> 热线-251222-074443 | BW20: 七有五性,劳有所得 | BX20: =IF(COUNTIF(BV:BV,BV20)=1,"否","是") -> 否 | BY20: =MID(AR20,18,1) | CG20: =VLOOKUP(AR20,[1]市民意见信息导出!$AI$2:$AK$392,3,FALSE()) -> 结束 | CH20: =VLOOKUP(BV20,[2]Sheet1!$C$2:$AC$99,2,FALSE()) -> #N/A
A21: 热线-251223-071646-3（1个附件） | B21: 2025-12-23 20:41:51 | C21: 2025-12-23 20:52:29 | D21: 2025-12-23 20:56:51 | E21: 高先生 | F21: 男 | G21: 手机,18701035101; | H21: 市民反映，12月23号双峪车站（去往新桥方向）的992路公交车没有窗帘，而且车内还很脏乱，市民认为作为交通运输服务行业，窗帘是最基本的，原来反映过其他车队，给出回复说没钱，市民不认可，市民表示问题没有解决，来电反映公交车没有窗帘问题。科信 安服 鸿运承 | I21: 是 | J21: 诉求 | K21: 行车安全服务部 | L21: 企业政策问题 | M21: 调整服务规范 | N21: 鸿运承物业管理中心 | O21: 河滩分中心 | P21: 物管行政部 | Q21: 河滩分中心 | R21: 2025-12-30 23:59:59 | S21: 2025-12-24 | T21: 2025-12-28 08:59:59 | U21: 结束 | V21: 0 | W21: 您好，关于您反映问题的办理情况，鸿运承物业管理中心河滩分中心现对您回复如下： | X21: 我分中心已于2025年12月24日下午13点59分对您进行电话回复，我对您没有答复完整，通话中您在与其他人对话，故我冒昧给您发送短信告诉您一下我们对您反映问题的办理结果。办理人：杨壑松；部门：鸿运承物业管理中心河滩分中心；职务；物管副主任。审核人：郑楠；部门：鸿运承物业管理中心物管行政部；职务：物管员。 | Y21: 高先生您好，992路公交车我们在龙泉西场站进行洗车服务工作，您所述车辆运营中车内很脏乱的问题我们非常重视您的反馈，由于我们的工作没有做好，992路给您带来不好的乘车体验，实在是抱歉，高先生。该线路车辆回到龙泉西场站后，在日常工作时段内，我们的保洁员已对车内卫生进行了全面的清理，确保我们的出场车辆卫生符合企业标准。您反馈的问题我们已整改完毕，同时我们要求保洁员对992路所有运营车辆的卫生再次进行细化清理。我们对于运营车辆车内卫生的清洁工作是一直在做的，也从未停止，已经形成了长效的清洁机制，但有时候卫生清洁工作我们做的还有不尽人意之处，您多多谅解。部分车辆车内未安装窗帘的问题，待车队配齐窗帘后，我们会立即进行安装。 | Z21: 我们分中心及场站班组长再次与992路的保洁人员进行了沟通，日常工作中我们要把清洁质量做的更加细致，同时加强保洁员清洁技能的培训，熟练掌握清洁方法，确保给您带来一个干净、整洁的出行环境。 | AA21: 我们定期会召开车辆保洁专题会议，开展车辆卫生专项检查，日常工作中我们加大巡检力度，强化制度建设，不断提高管理水平。 | AB21: 您好，关于您反映问题的办理情况，鸿运承物业管理中心河滩分中心现对您回复如下：高先生您好，992路公交车我们在龙泉西场站进行洗车服务工作，您所述车辆运营中车内很脏乱的问题我们非常重视您的反馈，由于我们的工作没有做好，992路给您带来不好的乘车体验，实在是抱歉，高先生。该线路车辆回到龙泉西场站后，在日常工作时段内，我们的保洁员已对车内卫生进行了全面的清理，确保我们的出场车辆卫生符合企业标准。您反馈的问题我们已整改完毕，同时我们要求保洁员对992路所有运营车辆的卫生再次进行细化清理。我们对于运营车辆车内卫生的清洁工作是一直在做的，也从未停止，已经形成了长效的清洁机制，但有时候卫生清洁工作我们做的还有不尽人意之处，您多多谅解。部分车辆车内未安装窗帘的问题，待车队配齐窗帘后，我们会立即进行安装。我们定期会召开车辆保洁专题会议，开展车辆卫生专项检查，日常工作中我们加大巡检力度，强化制度建设，不断提高管理水平。我分中心已于2025年12月24日下午13点59分对您进行电话回复，我对您没有答复完整，通话中您在与其他人对话，故我冒昧给您发送短信告诉您一下我们对您反映问题的办理结果。我们分中心及场站班组长再次与992路的保洁人员进行了沟通，日常工作中我们要把清洁质量做的更加细致，同时加强保洁员清洁技能的培训，熟练掌握清洁方法，确保给您带来一个干净、整洁的出行环境。欢迎您随时对我们的工作进行监督，感谢您提出宝贵意见，给您的出行带来的不便我们和您说声抱歉，谢谢您的支持与谅解。 | AC21: 满意 | AD21: 个人 | AE21: 2025-12-23 20:31:05 | AF21: 1725545789 | AG21: 设施设备 | AH21: 否 | AK21: =AG21&L21&M21 -> 设施设备企业政策问题调整服务规范 | AP21: 17 | AQ21: 46023 | AR21: =IFERROR(LEFT(A21,FIND("（",A21)-1),A21) -> 热线-251223-071646-3 | AS21: =J21 -> 诉求 | AT21: =IF(MID(AR21,1,2)="热线",12345)+IF(MID(AR21,1,2)="网络",12345) -> 12345 | AU21: =IFERROR(LEFT(D21,FIND(" ",D21)-1),D21) -> 2025-12-23 | AV21: =P21 -> 物管行政部 | AW21: =Q21 -> 河滩分中心 | AX21: =H21 -> 市民反映，12月23号双峪车站（去往新桥方向）的992路公交车没有窗帘，而且车内还很脏乱，市民认为作为交通运输服务行业，窗帘是最基本的，原来反映过其他车队，给出回复说没钱，市民不认可，市民表示问题没有解决，来电反映公交车没有窗帘问题。科信 安服 鸿运承 | AY21: =AG21 -> 设施设备 | AZ21: 否 | BA21: 否 | BB21: 否 | BC21: 七有五性,宜居性 | BD21: =U21 -> 结束 | BE21: =IFERROR(LEFT(T21,FIND(" ",T21)-1),T21) -> 2025-12-28 | BF21: 车辆卫生问题 （车内脏、窗帘） | BG21: 物管行政部 | BH21: 河滩分中心 | BL21: =IF(BG21="物管行政部","侯旭、郑楠",IF(BG21="安保部","张耕",IF(BG21="工程设备部","华菲",IF(BG21="人力资源部","成琦",IF(BG21="党委工作部","阎鑫雨",IF(BG21="餐饮服务部","赵弘晨",IF(BG21="工会","郑欣",IF(BG21="办公室","董娜",""))))))))&IF(BG21="纪检部","黄倩",IF(BG21="信息管理部","蔡浩然","")) -> 侯旭、郑楠 | BM21: 未主动剔除 | BP21: 业务类 | BV21: =MID(AR21,1,16) -> 热线-251223-071646 | BW21: 七有五性,便利性 | BX21: =IF(COUNTIF(BV:BV,BV21)=1,"否","是") -> 否 | BY21: =MID(AR21,18,1) -> 3 | CG21: =VLOOKUP(AR21,[1]市民意见信息导出!$AI$2:$AK$392,3,FALSE()) -> 结束 | CH21: =VLOOKUP(BV21,[2]Sheet1!$C$2:$AC$99,2,FALSE()) -> #N/A
A22: 热线-251223-074632（3个附件） | B22: 2025-12-23 22:03:04 | C22: 2025-12-24 00:13:27 | D22: 2025-12-24 08:38:42 | E22: 刘先生 | F22: 男 | G22: 手机,15210598471; | H22: 市民反映，朝阳区朝阳五路居公交场站（117路与107路等车辆），门口保安人员向路侧建安东路停车人员主动索要停车费，不交费不让停车，市民表示公交场站门口建安东路路段是违停路段，属于非法索要停车费，要求核查，来电反映非法索要停车费问题。 | I22: 是 | J22: 诉求 | K22: 安保部（应急管理中心） | L22: 场站保安问题 | M22: 场站保安 | N22: 鸿运承物业管理中心 | O22: 小营分中心 | P22: 安保部（应急管理中心） | Q22: 小营分中心 | R22: 2025-12-30 23:59:59 | S22: 2025-12-24 | T22: 2025-12-28 08:59:59 | U22: 结束 | V22: 0 | W22: 市民反映，朝阳区朝阳五路居公交场站（117路与107路等车辆），门口保安人员向路侧建安东路停车人员主动索要停车费，不交费不让停车，市民表示公交场站门口建安东路路段是违停路段，属于非法索要停车费，要求核查，来电反映非法索要停车费问题。经核实： 经核实：分中心接到投诉人所反映的问题后，给予了高度重视，第一时间与场站班长及保安负责人进行了核实，核实后是投诉人停车的位置属于公交车进出入场站的必要位置，门岗警卫人员也告知了投诉人此处不能停车，容易产生安全隐患，并告知投诉人场站门放置了锥桶，并也没有向投诉人所反映的门岗警卫人员存在，向车主收取费用一事，故与投诉人所说内容不属实申请剔除。与投诉人电话回访后，以得到投诉人的理解。 | X22: 回访情况：2025年12月24日下午10:34分，电话回访市民，以得到市民的谅解（回访电话：13439848360）办理人：何少楠。审核员：贾志尧。单位：小营分中心。职务：副主任 | Y22: 分中心再次对门岗警卫值守加强检查，及时发现问题后立即作出相关处理。 | Z22: 对场站所有的警卫职工，在岗期间继续履行好自己的岗位职责，严格按照物业公司对门岗警卫人员工作要求的相关文件，做好本职工作， 分中心对在其在职保安公司人员，进行严格检查及培训。发现问题第一时间整改，做出处理。 | AA22: 对场站所有的警卫职工，分中心要求在岗期间继续履行好自己的岗位职责，做到生人必问，生车必拦做到登记工作。 | AB22: 市民反映，朝阳区朝阳五路居公交场站（117路与107路等车辆），门口保安人员向路侧建安东路停车人员主动索要停车费，不交费不让停车，市民表示公交场站门口建安东路路段是违停路段，属于非法索要停车费，要求核查，来电反映非法索要停车费问题。经核实： 经核实：分中心接到投诉人所反映的问题后，给予了高度重视，第一时间与场站班长及保安负责人进行了核实，核实后是投诉人停车的位置属于公交车进出入场站的必要位置，门岗警卫人员也告知了投诉人此处不能停车，容易产生安全隐患，并告知投诉人场站门放置了锥桶，并也没有向投诉人所反映的门岗警卫人员存在，向车主收取费用一事，故与投诉人所说内容不属实申请剔除。与投诉人电话回访后，以得到投诉人的理解。 | AC22: 满意 | AD22: 个人 | AE22: 2025-12-23 21:49:47 | AF22: 1741937704 | AG22: 服务 | AH22: 否 | AK22: =AG22&L22&M22 -> 服务场站保安问题场站保安 | AP22: 18 | AQ22: 46023 | AR22: =IFERROR(LEFT(A22,FIND("（",A22)-1),A22) -> 热线-251223-074632 | AS22: =J22 -> 诉求 | AT22: =IF(MID(AR22,1,2)="热线",12345)+IF(MID(AR22,1,2)="网络",12345) -> 12345 | AU22: =IFERROR(LEFT(D22,FIND(" ",D22)-1),D22) -> 2025-12-24 | AV22: =P22 -> 安保部（应急管理中心） | AW22: =Q22 -> 小营分中心 | AX22: =H22 -> 市民反映，朝阳区朝阳五路居公交场站（117路与107路等车辆），门口保安人员向路侧建安东路停车人员主动索要停车费，不交费不让停车，市民表示公交场站门口建安东路路段是违停路段，属于非法索要停车费，要求核查，来电反映非法索要停车费问题。 | AY22: =AG22 -> 服务 | AZ22: 否 | BA22: 否 | BB22: 否 | BC22: 七有五性,安全性,便利性 | BD22: =U22 -> 结束 | BE22: =IFERROR(LEFT(T22,FIND(" ",T22)-1),T22) -> 2025-12-28 | BF22: 场站安保问题 （私家车停车收费） | BG22: 安保部 | BH22: 小营分中心 | BL22: =IF(BG22="物管行政部","侯旭、郑楠",IF(BG22="安保部","张耕",IF(BG22="工程设备部","华菲",IF(BG22="人力资源部","成琦",IF(BG22="党委工作部","阎鑫雨",IF(BG22="餐饮服务部","赵弘晨",IF(BG22="工会","郑欣",IF(BG22="办公室","董娜",""))))))))&IF(BG22="纪检部","黄倩",IF(BG22="信息管理部","蔡浩然","")) -> 张耕 | BM22: 未主动剔除 | BP22: 业务类 | BV22: =MID(AR22,1,16) -> 热线-251223-074632 | BW22: 七有五性,便利性 | BX22: =IF(COUNTIF(BV:BV,BV22)=1,"否","是") -> 否 | BY22: =MID(AR22,18,1) | CG22: =VLOOKUP(AR22,[1]市民意见信息导出!$AI$2:$AK$392,3,FALSE()) -> 结束 | CH22: =VLOOKUP(BV22,[2]Sheet1!$C$2:$AC$99,2,FALSE()) -> #N/A
